Workbook

Sheet Punters club
B1: HE_MAN PUNTERS 2019
I2: PUNTER TOTAL ROI
B3: Week | C3: Better | D3: Investment | E3: Return | F3: ROI | G3: Win % | J3: Investment | K3: Return | L3: TOTAL ROI
B4: 1 | C4: Scott | D4: 30 | E4: 0 | F4: =E4-D4 -> -30 | G4: =F4/D4 -> -1 | I4: Scott | J4: =D4+D12+D20+D28+D36+D44+D48+D59 -> 219.72 | K4: =E4+E12+E20+E28+E36+E44+E48+E59 -> 60.77 | L4: =K4-J4 -> -158.95 | M4: =L5+L4 -> 52.77
B5: 1 | C5: Beau | D5: 30 | E5: 0 | F5: =E5-D5 -> -30 | G5: =F5/D5 -> -1 | I5: Beau | J5: =D5+D13+D21+D29+D37+D45+D49+D60 -> 210 | K5: =E5+E13+E21+E29+E37+E45+E49+E60 -> 421.72 | L5: =K5-J5 -> 211.72
B6: 2 | C6: James | D6: 30 | E6: 0 | F6: =E6-D6 -> -30 | G6: =F6/D6 -> -1 | I6: James | J6: =D6+D14+D22+D30+D38+D46+D61 -> 155 | K6: =E6+E14+E22+E30+E38+E46+E61 -> 135 | L6: =K6-J6 -> -20 | M6: =L7+L6 -> -142.5
B7: 2 | C7: BT | D7: 30 | E7: 0 | F7: =E7-D7 -> -30 | G7: =F7/D7 -> -1 | I7: BT | J7: =D7+D15+D23+D31+D39+D47+D50+D62 -> 210 | K7: =E7+E15+E23+E31+E39+E47+E50+E62 -> 87.5 | L7: =K7-J7 -> -122.5
B8: 3 | C8: Brendan | D8: 30 | E8: 249.43 | F8: =E8-D8 -> 219.43 | G8: =F8/D8 -> 7.3143333 | I8: Brendan | J8: =D8+D16+D24+D32+D40+D51+D55+D63 -> 210 | K8: =E8+E16+E24+E32+E40+E51+E55+E63 -> 258.29 | L8: =K8-J8 -> 48.29 | M8: =L9+L8 -> -161.71
B9: 3 | C9: Daniel | D9: 30 | E9: 0 | F9: =E9-D9 -> -30 | G9: =F9/D9 -> -1 | I9: Daniel | J9: =D9+D17+D25+D33+D41+D52+D56+D64 -> 210 | K9: =E9+E17+E25+E33+E41+E52+E56+E64 -> 0 | L9: =K9-J9 -> -210
B10: 4 | C10: Brenton | D10: 30 | E10: 0 | F10: =E10-D10 -> -30 | G10: =F10/D10 -> -1 | I10: Brenton | J10: =D10+D18+D26+D34+D42+D53+D57+D65 -> 210 | K10: =E10+E18+E26+E34+E42+E53+E57+E65 -> 319.56 | L10: =K10-J10 -> 109.56 | M10: =L11+L10 -> 52.99
B11: 4 | C11: Paul | D11: 30 | E11: 93.43 | F11: =E11-D11 -> 63.43 | G11: =F11/D11 -> 2.1143333 | I11: Paul | J11: =D11+D19+D27+D35+D43+D54+D58+D66 -> 210 | K11: =E11+E19+E27+E35+E43+E54+E58+E66 -> 153.43 | L11: =K11-J11 -> -56.57
B12: 5 | C12: Scott | D12: 30 | E12: 0 | F12: =E12-D12 -> -30 | G12: =F12/D12 -> -1 | M12: =SUM(K4:K11)-SUM(J4:J11) -> -198.45
B13: 5 | C13: Beau | D13: 30 | E13: 0 | F13: =E13-D13 -> -30 | G13: =F13/D13 -> -1 | J13: =SUM(J4:J12) -> 1634.72 | K13: =SUM(K4:K12) -> 1436.27
B14: 6 | C14: James | D14: 30 | E14: 0 | F14: =E14-D14 -> -30 | G14: =F14/D14 -> -1
B15: 6 | C15: BT | D15: 30 | E15: 0 | F15: =E15-D15 -> -30 | G15: =F15/D15 -> -1
B16: 7 | C16: Brendan | D16: 30 | E16: 0 | F16: =E16-D16 -> -30 | G16: =F16/D16 -> -1
B17: 7 | C17: Daniel | D17: 30 | E17: 0 | F17: =E17-D17 -> -30 | G17: =F17/D17 -> -1
B18: 8 | C18: Brenton | D18: 30 | E18: 0 | F18: =E18-D18 -> -30 | G18: =F18/D18 -> -1
B19: 8 | C19: Paul | D19: 30 | E19: 60 | F19: =E19-D19 -> 30 | G19: =F19/D19 -> 1
B20: 9 | C20: Scott | D20: 30 | E20: 0 | F20: =E20-D20 -> -30 | G20: =F20/D20 -> -1
B21: 9 | C21: Beau | D21: 30 | E21: 0 | F21: =E21-D21 -> -30 | G21: =F21/D21 -> -1
B22: 10 | C22: James | D22: 30 | E22: 0 | F22: =E22-D22 -> -30 | G22: =F22/D22 -> -1
B23: 10 | C23: BT | D23: 30 | E23: 87.5 | F23: =E23-D23 -> 57.5 | G23: =F23/D23 -> 1.9166667
B24: 11 | C24: Brendan | D24: 30 | E24: 0 | F24: =E24-D24 -> -30 | G24: =F24/D24 -> -1
B25: 11 | C25: Daniel | D25: 30 | E25: 0 | F25: =E25-D25 -> -30 | G25: =F25/D25 -> -1
... B37: 17 | C37: Beau | D37: 30 | E37: 0 | F37: =E37-D37 -> -30 | G37: =F37/D37 -> -1
A38: 43665 | B38: 18 | C38: James | D38: 5 | E38: 0 | F38: =E38-D38 -> -5 | G38: =F38/D38 -> -1
A39: 43665 | B39: 18 | C39: BT | D39: 30 | E39: 0 | F39: =E39-D39 -> -30 | G39: =F39/D39 -> -1
A40: 43672 | B40: 19 | C40: Brendan | D40: 30 | E40: 0 | F40: =E40-D40 -> -30 | G40: =F40/D40 -> -1
A41: 43672 | B41: 19 | C41: Daniel | D41: 30 | E41: 0 | F41: =E41-D41 -> -30 | G41: =F41/D41 -> -1
A42: 43679 | B42: 20 | C42: Brenton | D42: 30 | E42: =248.75+33.78 -> 282.53 | F42: =E42-D42 -> 252.53 | G42: =F42/D42 -> 8.4176667
A43: 43679 | B43: 20 | C43: Paul | D43: 30 | E43: 0 | F43: =E43-D43 -> -30 | G43: =F43/D43 -> -1
A44: 43686 | B44: 21 | C44: Scott | D44: =30-0.28 -> 29.72 | E44: 20.14 | F44: =E44-D44 -> -9.58 | G44: =F44/D44 -> -0.32234186
A45: 43686 | B45: 21 | C45: Beau | D45: 30 | E45: 0 | F45: =E45-D45 -> -30 | G45: =F45/D45 -> -1
B46: 22 | C46: James | D46: 30 | E46: 0 | F46: =E46-D46 -> -30 | G46: =F46/D46 -> -1
B47: 22 | C47: BT | D47: 30 | E47: 0 | F47: =E47-D47 -> -30 | G47: =F47/D47 -> -1
A48: bonus round | B48: 22 | C48: Scott | D48: 20 | E48: 0 | F48: =E48-D48 -> -20 | G48: =F48/D48 -> -1
B49: 22 | C49: Beau | D49: 20 | E49: 0 | F49: =E49-D49 -> -20 | G49: =F49/D49 -> -1
B50: 22 | C50: BT | D50: 20 | E50: 0 | F50: =E50-D50 -> -20 | G50: =F50/D50 -> -1
B51: 22 | C51: Brendan | D51: 20 | E51: 0 | F51: =E51-D51 -> -20 | G51: =F51/D51 -> -1
...

Sheet Punters 2020
C2: S. BAMFORD | E2: P. BLAKEY | G2: B. TURNOR | I2: B. JASKOLA | K2: K. HORNSEY | M2: J. VELLIOU | O2: D. MILEVSKI | Q2: B. RAFFAELE | S2: B. SPICER | U2: bonus bets | W2: WEEKLY TOTAL
B3: ROUND | C3: INVESTMENT | D3: RETURN | E3: INVESTMENT | F3: RETURN | G3: INVESTMENT | H3: RETURN | I3: INVESTMENT | J3: RETURN | K3: INVESTMENT | L3: RETURN | M3: INVESTMENT | N3: RETURN | O3: INVESTMENT | P3: RETURN | Q3: INVESTMENT | R3: RETURN | S3: INVESTMENT | T3: RETURN | U3: INVESTMENT | V3: RETURN | W3: INVESTMENT | X3: RETURN
B4: R1 | C4: 35 | D4: 0 | E4: 35 | F4: =39+41.25 -> 80.25 | G4: 35 | H4: 0 | I4: 35 | J4: 0 | S4: 45 | T4: 0 | U4: 0 | V4: 130 | W4: =U4+S4+Q4+O4+M4+K4+I4+G4+E4+C4 -> 185 | X4: =V4+T4+R4+P4+N4+L4+J4+H4+F4+D4 -> 210.25 | Y4: =W4 -> 185 | Z4: =X4 -> 210.25 | AA4: =Z4-Y4 -> 25.25
B5: Dogs | C5: 9.98 | D5: 0 | E5: 9.98 | F5: 0 | I5: =9.6+10+9.8 -> 29.4 | J5: 0 | S5: =10+14.96 -> 24.96 | T5: 0 | W5: =U5+S5+Q5+O5+M5+K5+I5+G5+E5+C5 -> 74.32 | X5: =V5+T5+R5+P5+N5+L5+J5+H5+F5+D5 -> 0 | Y5: =Y4+W5 -> 259.32 | Z5: =Z4+X5 -> 210.25 | AA5: =Z5-Y5 -> -49.07
B6: R2 | I6: 35 | J6: 0 | K6: 35 | L6: 0 | M6: 35 | N6: 0 | W6: =U6+S6+Q6+O6+M6+K6+I6+G6+E6+C6 -> 105 | X6: =V6+T6+R6+P6+N6+L6+J6+H6+F6+D6 -> 0 | Y6: =Y5+W6 -> 364.32 | Z6: =Z5+X6 -> 210.25 | AA6: =Z6-Y6 -> -154.07
B7: R3 | O7: 35 | P7: 0 | Q7: 35 | R7: 0 | S7: 35 | T7: 0 | W7: =U7+S7+Q7+O7+M7+K7+I7+G7+E7+C7 -> 105 | X7: =V7+T7+R7+P7+N7+L7+J7+H7+F7+D7 -> 0 | Y7: =Y6+W7 -> 469.32 | Z7: =Z6+X7 -> 210.25 | AA7: =Z7-Y7 -> -259.07
B8: R4 | C8: 25 | D8: 278.32 | E8: 37 | F8: 0 | G8: 30 | H8: 23.75 | W8: =U8+S8+Q8+O8+M8+K8+I8+G8+E8+C8 -> 92 | X8: =V8+T8+R8+P8+N8+L8+J8+H8+F8+D8 -> 302.07 | Y8: =Y7+W8 -> 561.32 | Z8: =Z7+X8 -> 512.32 | AA8: =Z8-Y8 -> -49
B9: R5 | I9: 35 | J9: 52.5 | K9: 0 | L9: 0 | M9: 35 | N9: 206.25 | W9: =U9+S9+Q9+O9+M9+K9+I9+G9+E9+C9 -> 70 | X9: =V9+T9+R9+P9+N9+L9+J9+H9+F9+D9 -> 258.75 | Y9: =Y8+W9 -> 631.32 | Z9: =Z8+X9 -> 771.07 | AA9: =Z9-Y9 -> 139.75
B10: R6 | O10: 35 | P10: 0 | Q10: 35 | R10: 0 | S10: 38 | T10: 0 | W10: =U10+S10+Q10+O10+M10+K10+I10+G10+E10+C10 -> 108 | X10: =V10+T10+R10+P10+N10+L10+J10+H10+F10+D10 -> 0 | Y10: =Y9+W10 -> 739.32 | Z10: =Z9+X10 -> 771.07 | AA10: =Z10-Y10 -> 31.75
B11: R7 | C11: 35 | D11: 0 | E11: 35 | F11: 0 | G11: 35 | H11: 221.13 | W11: =U11+S11+Q11+O11+M11+K11+I11+G11+E11+C11 -> 105 | X11: =V11+T11+R11+P11+N11+L11+J11+H11+F11+D11 -> 221.13 | Y11: =Y10+W11 -> 844.32 | Z11: =Z10+X11 -> 992.2 | AA11: =Z11-Y11 -> 147.88
B12: R8 | I12: 35 | J12: 0 | K12: 70 | L12: 0 | M12: 35 | N12: 0 | W12: =U12+S12+Q12+O12+M12+K12+I12+G12+E12+C12 -> 140 | X12: =V12+T12+R12+P12+N12+L12+J12+H12+F12+D12 -> 0 | Y12: =Y11+W12 -> 984.32 | Z12: =Z11+X12 -> 992.2 | AA12: =Z12-Y12 -> 7.88
B13: R9 | O13: 35 | P13: 0 | Q13: 35 | R13: 0 | S13: 35 | T13: 0 | W13: =U13+S13+Q13+O13+M13+K13+I13+G13+E13+C13 -> 105 | X13: =V13+T13+R13+P13+N13+L13+J13+H13+F13+D13 -> 0 | Y13: =Y12+W13 -> 1089.32 | Z13: =Z12+X13 -> 992.2 | AA13: =Z13-Y13 -> -97.12
B14: R10 | C14: 35 | D14: 0 | E14: 30 | F14: 0 | G14: 35 | H14: 70 | W14: =U14+S14+Q14+O14+M14+K14+I14+G14+E14+C14 -> 100 | X14: =V14+T14+R14+P14+N14+L14+J14+H14+F14+D14 -> 70 | Y14: =Y13+W14 -> 1189.32 | Z14: =Z13+X14 -> 1062.2 | AA14: =Z14-Y14 -> -127.12
B15: R11 | I15: 35 | J15: 0 | K15: 30 | L15: 0 | M15: 35 | N15: 0 | W15: =U15+S15+Q15+O15+M15+K15+I15+G15+E15+C15 -> 100 | X15: =V15+T15+R15+P15+N15+L15+J15+H15+F15+D15 -> 0 | Y15: =Y14+W15 -> 1289.32 | Z15: =Z14+X15 -> 1062.2 | AA15: =Z15-Y15 -> -227.12
B16: R12 | O16: 35 | P16: 0 | Q16: 35 | R16: 0 | S16: 35 | T16: 103.5 | W16: =U16+S16+Q16+O16+M16+K16+I16+G16+E16+C16 -> 105 | X16: =V16+T16+R16+P16+N16+L16+J16+H16+F16+D16 -> 103.5 | Y16: =Y15+W16 -> 1394.32 | Z16: =Z15+X16 -> 1165.7 | AA16: =Z16-Y16 -> -228.62
B17: R13 | C17: 35 | D17: 0 | E17: 30 | F17: 0 | G17: 35 | H17: 0 | W17: =U17+S17+Q17+O17+M17+K17+I17+G17+E17+C17 -> 100 | X17: =V17+T17+R17+P17+N17+L17+J17+H17+F17+D17 -> 0 | Y17: =Y16+W17 -> 1494.32 | Z17: =Z16+X17 -> 1165.7 | AA17: =Z17-Y17 -> -328.62
B18: R14 | I18: 20 | J18: 0 | K18: 30 | L18: 0 | M18: 30 | N18: 0 | W18: =U18+S18+Q18+O18+M18+K18+I18+G18+E18+C18 -> 80 | X18: =V18+T18+R18+P18+N18+L18+J18+H18+F18+D18 -> 0 | Y18: =Y17+W18 -> 1574.32 | Z18: =Z17+X18 -> 1165.7 | AA18: =Z18-Y18 -> -408.62
B19: R15 | O19: 35 | P19: 0 | Q19: 35 | R19: 0 | S19: 35 | T19: 20.6 | W19: =U19+S19+Q19+O19+M19+K19+I19+G19+E19+C19 -> 105 | X19: =V19+T19+R19+P19+N19+L19+J19+H19+F19+D19 -> 20.6 | Y19: =Y18+W19 -> 1679.32 | Z19: =Z18+X19 -> 1186.3 | AA19: =Z19-Y19 -> -493.02
B20: R16 | C20: 35 | D20: 0 | E20: 35 | F20: 0 | G20: 35 | H20: 0 | W20: =U20+S20+Q20+O20+M20+K20+I20+G20+E20+C20 -> 105 | X20: =V20+T20+R20+P20+N20+L20+J20+H20+F20+D20 -> 0 | Y20: =Y19+W20 -> 1784.32 | Z20: =Z19+X20 -> 1186.3 | AA20: =Z20-Y20 -> -598.02
B21: R17 | I21: 35 | J21: =93.39+77.65 -> 171.04 | K21: 45 | L21: 0 | M21: 35 | N21: 0 | W21: =U21+S21+Q21+O21+M21+K21+I21+G21+E21+C21 -> 115 | X21: =V21+T21+R21+P21+N21+L21+J21+H21+F21+D21 -> 171.04 | Y21: =Y20+W21 -> 1899.32 | Z21: =Z20+X21 -> 1357.34 | AA21: =Z21-Y21 -> -541.98
B22: R18 | O22: 35 | P22: 0 | Q22: 35 | R22: 94.92 | S22: 35 | T22: =39.44+142.5 -> 181.94 | W22: =U22+S22+Q22+O22+M22+K22+I22+G22+E22+C22 -> 105 | X22: =V22+T22+R22+P22+N22+L22+J22+H22+F22+D22 -> 276.86 | Y22: =Y21+W22 -> 2004.32 | Z22: =Z21+X22 -> 1634.2 | AA22: =Z22-Y22 -> -370.12
B23: F1 | C23: 35 | D23: 0 | E23: 40 | F23: 140.49 | G23: 80 | H23: 0 | W23: =U23+S23+Q23+O23+M23+K23+I23+G23+E23+C23 -> 155 | X23: =V23+T23+R23+P23+N23+L23+J23+H23+F23+D23 -> 140.49 | Y23: =Y22+W23 -> 2159.32 | Z23: =Z22+X23 -> 1774.69 | AA23: =Z23-Y23 -> -384.63
B24: F2 | I24: 25 | J24: 0 | K24: 15 | L24: 0 | M24: 10 | N24: 0 | W24: =U24+S24+Q24+O24+M24+K24+I24+G24+E24+C24 -> 50 | X24: =V24+T24+R24+P24+N24+L24+J24+H24+F24+D24 -> 0 | Y24: =Y23+W24 -> 2209.32 | Z24: =Z23+X24 -> 1774.69 | AA24: =Z24-Y24 -> -434.63
B25: F3 | O25: 35.1 | P25: 0 | Q25: 35 | R25: 0 | S25: 35 | T25: 0 | W25: =U25+S25+Q25+O25+M25+K25+I25+G25+E25+C25 -> 105.1 | X25: =V25+T25+R25+P25+N25+L25+J25+H25+F25+D25 -> 0 | Y25: =Y24+W25 -> 2314.42 | Z25: =Z24+X25 -> 1774.69 | AA25: =Z25-Y25 -> -539.73
B26: GF | C26: 20 | D26: 0 | E26: 25 | F26: 0 | G26: 20 | H26: 0 | I26: 10 | J26: 0 | K26: 0 | L26: 0 | M26: 20 | N26: 0 | O26: 20 | P26: 0 | Q26: 20 | R26: 0 | S26: 20 | T26: 0 | W26: =U26+S26+Q26+O26+M26+K26+I26+G26+E26+C26 -> 155 | X26: =V26+T26+R26+P26+N26+L26+J26+H26+F26+D26 -> 0 | Y26: =Y25+W26 -> 2469.42 | Z26: =Z25+X26 -> 1774.69 | AA26: =Z26-Y26 -> -694.73
B27: total | C27: =SUM(C4:C26) -> 264.98 | D27: =SUM(D4:D26) -> 278.32 | E27: =SUM(E4:E26) -> 276.98 | F27: =SUM(F4:F26) -> 220.74 | G27: =SUM(G4:G26) -> 305 | H27: =SUM(H4:H26) -> 314.88 | I27: =SUM(I4:I26) -> 294.4 | J27: =SUM(J4:J26) -> 223.54 | ... X27: =SUM(X4:X26) -> 1774.69
D28: =(D27-C27)/C27 -> 0.050343422 | F28: =(F27-E27)/E27 -> -0.20304715 | H28: =(H27-G27)/G27 -> 0.032393443 | J28: =(J27-I27)/I27 -> -0.24069293 | L28: =(L27-K27)/K27 -> -1 | N28: =(N27-M27)/M27 -> -0.12234043 | P28: =(P27-O27)/O27 -> -1 | R28: =(R27-Q27)/Q27 -> -0.64181132 | T28: =(T27-S27)/S27 -> -0.094449047
F29: TOTAL INVESTMENT | I29: =C27+E27+G27+I27+K27+M27+O27+Q27+S27+U27 -> 2469.42
G30: TOTAL RETURNS | I30: =+D27+F27+H27+J27+L27+N27+P27+R27+T27+V27 -> 1774.69
I31: =I30-I29 -> -694.73
C32: =C27+E27+G27 -> 846.96 | D32: =D27+F27+H27 -> 813.94 | E32: =D32-C32 -> -33.02 | I32: =I27+K27+M27 -> 754.4 | J32: =J27+L27+N27 -> 429.79 | K32: =J32-I32 -> -324.61 | O32: =O27+Q27+S27 -> 868.06 | P32: =P27+R27+T27 -> 400.96 | Q32: =P32-O32 -> -467.1
G33: initial | I33: 1200
I34: =I33+I31 -> 505.27
C38: =C27+E27+G27 -> 846.96 | D38: =D27+F27+H27 -> 813.94 | I38: =I27+K27+M27 -> 754.4 | J38: =J27+L27+N27 -> 429.79 | O38: =O27+Q27+S27 -> 868.06 | P38: =P27+R27+T27 -> 400.96
D39: =D38-C38 -> -33.02 | J39: =J38-I38 -> -324.61 | P39: =P38-O38 -> -467.1

Sheet Punters 2021
C2: S. BAMFORD | E2: K. HORNSEY | G2: B. JASKOLA | I2: B. TURNOR | K2: P. BLAKEY | M2: B. RAFFAELE | O2: D. MILEVSKI | Q2: J. VELLIOU | S2: B. SPICER | U2: bonus bets | W2: WEEKLY TOTAL
B3: ROUND | C3: INVESTMENT | D3: RETURN | E3: INVESTMENT | F3: RETURN | G3: INVESTMENT | H3: RETURN | I3: INVESTMENT | J3: RETURN | K3: INVESTMENT | L3: RETURN | M3: INVESTMENT | N3: RETURN | O3: INVESTMENT | P3: RETURN | Q3: INVESTMENT | R3: RETURN | S3: INVESTMENT | T3: RETURN | U3: INVESTMENT | V3: RETURN | W3: INVESTMENT | X3: RETURN
B4: R1 | C4: 8 | D4: 0 | E4: 8 | F4: 0 | G4: 8 | H4: 0 | I4: 8 | J4: 0 | K4: 8 | L4: 43.63 | M4: 8 | N4: 0 | O4: 8 | P4: 0 | Q4: 8 | R4: 0 | S4: 8 | T4: 0 | W4: =U4+S4+Q4+O4+M4+K4+I4+G4+E4+C4 -> 72 | X4: =V4+T4+R4+P4+N4+L4+J4+H4+F4+D4 -> 43.63
B5: R2 | C5: 8 | D5: 0 | E5: 8 | F5: 0 | G5: 8 | H5: 49.35 | I5: 8 | J5: 0 | K5: 8 | L5: 0 | M5: 8 | N5: 0 | O5: 8 | P5: 0 | Q5: 8 | R5: 0 | S5: 8 | T5: 0 | W5: =U5+S5+Q5+O5+M5+K5+I5+G5+E5+C5 -> 72 | X5: =V5+T5+R5+P5+N5+L5+J5+H5+F5+D5 -> 49.35
B6: R3 | C6: 26 | D6: 0 | E6: 24 | F6: 0 | G6: 26 | H6: 0 | W6: =U6+S6+Q6+O6+M6+K6+I6+G6+E6+C6 -> 76 | X6: =V6+T6+R6+P6+N6+L6+J6+H6+F6+D6 -> 0
B7: R4 | I7: 26 | J7: 0 | K7: 26 | L7: 0 | M7: 26 | N7: 0 | W7: =U7+S7+Q7+O7+M7+K7+I7+G7+E7+C7 -> 78 | X7: =V7+T7+R7+P7+N7+L7+J7+H7+F7+D7 -> 0
B8: R5 | O8: 26 | P8: 0 | Q8: 28 | R8: 0 | S8: 26 | T8: 0 | W8: =U8+S8+Q8+O8+M8+K8+I8+G8+E8+C8 -> 80 | X8: =V8+T8+R8+P8+N8+L8+J8+H8+F8+D8 -> 0
B9: R6 | C9: 26 | D9: 0 | E9: 26 | F9: 0 | G9: 26 | H9: 44.38 | W9: =U9+S9+Q9+O9+M9+K9+I9+G9+E9+C9 -> 78 | X9: =V9+T9+R9+P9+N9+L9+J9+H9+F9+D9 -> 44.38
B10: R7 | I10: 26 | J10: 0 | K10: 26 | L10: 0 | M10: 26 | N10: 0 | W10: =U10+S10+Q10+O10+M10+K10+I10+G10+E10+C10 -> 78 | X10: =V10+T10+R10+P10+N10+L10+J10+H10+F10+D10 -> 0
B11: R8 | O11: 25 | P11: 0 | Q11: 20 | R11: 0 | S11: 26 | T11: 0 | W11: =U11+S11+Q11+O11+M11+K11+I11+G11+E11+C11 -> 71 | X11: =V11+T11+R11+P11+N11+L11+J11+H11+F11+D11 -> 0
B12: R9 | C12: 26 | D12: 1122 | E12: 32 | F12: 0 | G12: 26 | H12: 0 | W12: =U12+S12+Q12+O12+M12+K12+I12+G12+E12+C12 -> 84 | X12: =V12+T12+R12+P12+N12+L12+J12+H12+F12+D12 -> 1122
B13: R10 | I13: 26 | J13: 0 | K13: 26 | L13: 70 | M13: 26 | N13: 0 | W13: =U13+S13+Q13+O13+M13+K13+I13+G13+E13+C13 -> 78 | X13: =V13+T13+R13+P13+N13+L13+J13+H13+F13+D13 -> 70
B14: R11 | O14: 26 | P14: 0 | Q14: 36 | R14: 185 | S14: 26 | T14: 0 | W14: =U14+S14+Q14+O14+M14+K14+I14+G14+E14+C14 -> 88 | X14: =V14+T14+R14+P14+N14+L14+J14+H14+F14+D14 -> 185
B15: R12 | C15: 26 | D15: 0 | E15: 24 | F15: 0 | G15: 26 | H15: =207+290.25 -> 497.25 | W15: =U15+S15+Q15+O15+M15+K15+I15+G15+E15+C15 -> 76 | X15: =V15+T15+R15+P15+N15+L15+J15+H15+F15+D15 -> 497.25
B16: R13 | I16: 28 | J16: 0 | K16: 26 | L16: 0 | M16: 26 | N16: 0 | W16: =U16+S16+Q16+O16+M16+K16+I16+G16+E16+C16 -> 80 | X16: =V16+T16+R16+P16+N16+L16+J16+H16+F16+D16 -> 0
B17: R14 | O17: 25 | P17: 0 | Q17: 20 | R17: 0 | S17: 26 | T17: 0 | W17: =U17+S17+Q17+O17+M17+K17+I17+G17+E17+C17 -> 71 | X17: =V17+T17+R17+P17+N17+L17+J17+H17+F17+D17 -> 0
B18: R15 | C18: 26 | D18: 0 | E18: 26 | F18: 12 | G18: 26 | H18: 0 | W18: =U18+S18+Q18+O18+M18+K18+I18+G18+E18+C18 -> 78 | X18: =V18+T18+R18+P18+N18+L18+J18+H18+F18+D18 -> 12
B19: R16 | I19: 24 | J19: 0 | K19: 26 | L19: 73 | M19: 26 | N19: 0 | W19: =U19+S19+Q19+O19+M19+K19+I19+G19+E19+C19 -> 76 | X19: =V19+T19+R19+P19+N19+L19+J19+H19+F19+D19 -> 73
B20: R17 | O20: 26 | P20: 0 | Q20: 26 | R20: 0 | S20: 24 | T20: 0 | W20: =U20+S20+Q20+O20+M20+K20+I20+G20+E20+C20 -> 76 | X20: =V20+T20+R20+P20+N20+L20+J20+H20+F20+D20 -> 0
B21: R18 | C21: 26 | D21: 0 | E21: 34 | F21: 0 | G21: 23.5 | H21: 0 | W21: =U21+S21+Q21+O21+M21+K21+I21+G21+E21+C21 -> 83.5 | X21: =V21+T21+R21+P21+N21+L21+J21+H21+F21+D21 -> 0
B22: R19 | I22: 26 | J22: 101.5 | K22: 27.5 | L22: 0 | M22: 26 | N22: 0 | W22: =U22+S22+Q22+O22+M22+K22+I22+G22+E22+C22 -> 79.5 | X22: =V22+T22+R22+P22+N22+L22+J22+H22+F22+D22 -> 101.5
B23: R20 | O23: 26 | P23: 0 | Q23: 26 | R23: 0 | S23: 36 | T23: 0 | W23: =U23+S23+Q23+O23+M23+K23+I23+G23+E23+C23 -> 88 | X23: =V23+T23+R23+P23+N23+L23+J23+H23+F23+D23 -> 0
B24: R21 | C24: 26 | D24: 0 | E24: 26 | F24: 0 | G24: 16 | H24: 0 | W24: =U24+S24+Q24+O24+M24+K24+I24+G24+E24+C24 -> 68 | X24: =V24+T24+R24+P24+N24+L24+J24+H24+F24+D24 -> 0
B25: R22 | I25: 26 | J25: =46.46+246.99 -> 293.45 | K25: 26 | L25: 0 | M25: 26 | N25: 0 | W25: =U25+S25+Q25+O25+M25+K25+I25+G25+E25+C25 -> 78 | X25: =V25+T25+R25+P25+N25+L25+J25+H25+F25+D25 -> 293.45
B26: R23 | O26: =24.74+1.5 -> 26.24 | P26: 0.64 | Q26: 26 | R26: 0 | S26: 27 | T26: 0 | W26: =U26+S26+Q26+O26+M26+K26+I26+G26+E26+C26 -> 79.24 | X26: =V26+T26+R26+P26+N26+L26+J26+H26+F26+D26 -> 0.64
B27: total | C27: =SUM(C4:C26) -> 198 | D27: =SUM(D4:D26) -> 1122 | E27: =SUM(E4:E26) -> 208 | F27: =SUM(F4:F26) -> 12 | G27: =SUM(G4:G26) -> 185.5 | H27: =SUM(H4:H26) -> 590.98 | I27: =SUM(I4:I26) -> 198 | J27: =SUM(J4:J26) -> 394.95 | ... X27: =SUM(X4:X26) -> 2492.2
D28: =(D27-C27)/C27 -> 4.6666667 | F28: =(F27-E27)/E27 -> -0.94230769 | H28: =(H27-G27)/G27 -> 2.185876 | J28: =(J27-I27)/I27 -> 0.99469697 | L28: =(L27-K27)/K27 -> -0.064511278 | N28: =(N27-M27)/M27 -> -1 | P28: =(P27-O27)/O27 -> -0.99673869 | R28: =(R27-Q27)/Q27 -> -0.065656566 | T28: =(T27-S27)/S27 -> -1
F29: TOTAL INVESTMENT | I29: =C27+E27+G27+I27+K27+M27+O27+Q27+S27+U27 -> 1788.24
G30: TOTAL RETURNS | I30: =+D27+F27+H27+J27+L27+N27+P27+R27+T27+V27 -> 2492.2
I31: =I30-I29 -> 703.96
C32: =C27+E27+G27 -> 591.5 | D32: =D27+F27+H27 -> 1724.98 | E32: =D32-C32 -> 1133.48 | I32: =I27+K27+M27 -> 595.5 | J32: =J27+L27+N27 -> 581.58 | K32: =J32-I32 -> -13.92 | O32: =O27+Q27+S27 -> 601.24 | P32: =P27+R27+T27 -> 185.64 | Q32: =P32-O32 -> -415.6
G33: initial | I33: =400+100+100 -> 600
G34: BALANCE OF ACC | I34: =I33+I31 -> 1303.96
C38: =C27+E27+G27 -> 591.5 | D38: =D27+F27+H27 -> 1724.98 | I38: =I27+K27+M27 -> 595.5 | J38: =J27+L27+N27 -> 581.58 | O38: =O27+Q27+S27 -> 601.24 | P38: =P27+R27+T27 -> 185.64
D39: =D38-C38 -> 1133.48 | J39: =J38-I38 -> -13.92 | P39: =P38-O38 -> -415.6

Sheet Punters 2022
C2: J. VELLIOU | E2: B. TURNOR | G2: P. BLAKEY | I2: B. JASKOLA | K2: K. HORNSEY | M2: B. SPICER | O2: D. MILEVSKI | Q2: B. RAFFAELE | S2: S. BAMFORD | U2: S. CAPOZZI | W2: Group BET | Y2: WEEKLY TOTAL
B3: ROUND | C3: INVESTMENT | D3: RETURN | E3: INVESTMENT | F3: RETURN | G3: INVESTMENT | H3: RETURN | I3: INVESTMENT | J3: RETURN | K3: INVESTMENT | L3: RETURN | M3: INVESTMENT | N3: RETURN | O3: INVESTMENT | P3: RETURN | Q3: INVESTMENT | R3: RETURN | S3: INVESTMENT | T3: RETURN | U3: INVESTMENT | V3: RETURN | W3: INVESTMENT | X3: RETURN | Y3: INVESTMENT | Z3: RETURN
B4: R1 | C4: 10 | D4: 0 | E4: 10 | F4: 0 | G4: 10 | H4: 0 | I4: 10 | J4: 0 | K4: 10 | L4: 0 | M4: 10 | N4: 0 | O4: 10 | P4: 0 | Q4: 10 | R4: 0 | S4: 10 | T4: 0 | Y4: =U4+S4+Q4+O4+M4+K4+I4+G4+E4+C4 -> 90 | Z4: =V4+T4+R4+P4+N4+L4+J4+H4+F4+D4 -> 0 | AA4: =Y4 -> 90 | AB4: =Z4 -> 0 | AC4: =AB4-AA4 -> -90
B5: R2 | C5: 25 | D5: 0 | E5: 25 | F5: 0 | G5: 25 | H5: 0 | Y5: =U5+S5+Q5+O5+M5+K5+I5+G5+E5+C5 -> 75 | Z5: =V5+T5+R5+P5+N5+L5+J5+H5+F5+D5 -> 0 | AA5: =AA4+Y5 -> 165 | AB5: =AB4+Z5 -> 0 | AC5: =AB5-AA5 -> -165
B6: R3 | I6: 25 | J6: 0 | K6: 25 | L6: 0 | M6: 25 | N6: 0 | Y6: =U6+S6+Q6+O6+M6+K6+I6+G6+E6+C6 -> 75 | Z6: =V6+T6+R6+P6+N6+L6+J6+H6+F6+D6 -> 0 | AA6: =AA5+Y6 -> 240 | AB6: =AB5+Z6 -> 0 | AC6: =AB6-AA6 -> -240 | AE6: bets | AF6: return | AG6: summary | AH6: percentage
B7: R4 | O7: 25 | P7: 0 | Q7: 25 | R7: 71.54 | S7: 25 | T7: 0 | Y7: =U7+S7+Q7+O7+M7+K7+I7+G7+E7+C7 -> 75 | Z7: =V7+T7+R7+P7+N7+L7+J7+H7+F7+D7 -> 71.54 | AA7: =AA6+Y7 -> 315 | AB7: =AB6+Z7 -> 71.54 | AC7: =AB7-AA7 -> -243.46 | AD7: moose | AE7: =+C29+'Punters 2021'!Q27+'Punters 2020'!M27+'Punters club'!J6 -> 788 | AF7: =+D29+'Punters 2021'!R27+'Punters 2020'!N27+'Punters club'!K6 -> 534 | AG7: =+AF7-AE7 -> -254 | AH7: =(AF7-AE7)/AE7 -> -0.32233503
B8: R5 | C8: 25 | D8: 0 | E8: 25 | F8: 0 | G8: 25 | H8: 0 | Y8: =U8+S8+Q8+O8+M8+K8+I8+G8+E8+C8 -> 75 | Z8: =V8+T8+R8+P8+N8+L8+J8+H8+F8+D8 -> 0 | AA8: =AA7+Y8 -> 390 | AB8: =AB7+Z8 -> 71.54 | AC8: =AB8-AA8 -> -318.46 | AD8: bt | AE8: =+E29+'Punters 2021'!I27+'Punters 2020'!G27+'Punters club'!J7 -> 923 | AF8: =+F29+'Punters 2021'!J27+'Punters 2020'!H27+'Punters club'!K7 -> 1019.77 | AG8: =+AF8-AE8 -> 96.77 | AH8: =(AF8-AE8)/AE8 -> 0.1048429
B9: R6 | I9: 25 | J9: 0 | K9: 25 | L9: 0 | M9: 25 | N9: 0 | Y9: =U9+S9+Q9+O9+M9+K9+I9+G9+E9+C9 -> 75 | Z9: =V9+T9+R9+P9+N9+L9+J9+H9+F9+D9 -> 0 | AA9: =AA8+Y9 -> 465 | AB9: =AB8+Z9 -> 71.54 | AC9: =AB9-AA9 -> -393.46 | AD9: blakey | AE9: =+G29+'Punters 2021'!K27+'Punters 2020'!E27+'Punters club'!J11 -> 896.48 | AF9: =+H29+'Punters 2021'!L27+'Punters 2020'!F27+'Punters club'!K11 -> 961.4 | AG9: =+AF9-AE9 -> 64.92 | AH9: =(AF9-AE9)/AE9 -> 0.072416563
B10: R7 | O10: 25 | P10: 0 | Q10: 25 | R10: 0 | S10: 25 | T10: 0 | U10: 25 | V10: 0 | Y10: =U10+S10+Q10+O10+M10+K10+I10+G10+E10+C10 -> 100 | Z10: =V10+T10+R10+P10+N10+L10+J10+H10+F10+D10 -> 0 | AA10: =AA9+Y10 -> 565 | AB10: =AB9+Z10 -> 71.54 | AC10: =AB10-AA10 -> -493.46 | AD10: fake | AE10: =+I29+'Punters 2021'!G27+'Punters 2020'!I27+'Punters club'!J10 -> 899.9 | AF10: =+J29+'Punters 2021'!H27+'Punters 2020'!J27+'Punters club'!K10 -> 1459.9 | AG10: =+AF10-AE10 -> 560 | AH10: =(AF10-AE10)/AE10 -> 0.62229137
B11: R8 | C11: 25 | D11: 0 | E11: 25 | F11: 108 | G11: 25 | H11: 0 | Y11: =U11+S11+Q11+O11+M11+K11+I11+G11+E11+C11 -> 75 | Z11: =V11+T11+R11+P11+N11+L11+J11+H11+F11+D11 -> 108 | AA11: =AA10+Y11 -> 640 | AB11: =AB10+Z11 -> 179.54 | AC11: =AB11-AA11 -> -460.46 | AD11: kane | AE11: =+K29+'Punters 2021'!E27+'Punters 2020'!K27 -> 633 | AF11: =+L29+'Punters 2021'!F27+'Punters 2020'!L27 -> 58.25 | AG11: =+AF11-AE11 -> -574.75 | AH11: =(AF11-AE11)/AE11 -> -0.90797788
B12: R9 | I12: =5+2.5+2.5+5+2.5+7+0.5 -> 25 | J12: 0 | K12: =5+10+10 -> 25 | L12: 0 | M12: 25 | N12: 0 | Y12: =U12+S12+Q12+O12+M12+K12+I12+G12+E12+C12 -> 75 | Z12: =V12+T12+R12+P12+N12+L12+J12+H12+F12+D12 -> 0 | AA12: =AA11+Y12 -> 715 | AB12: =AB11+Z12 -> 179.54 | AC12: =AB12-AA12 -> -535.46 | AD12: spicer | AE12: =+M29+'Punters 2021'!S27+'Punters 2020'!S27+'Punters club'!J8 -> 954.96 | AF12: =+N29+'Punters 2021'!T27+'Punters 2020'!T27+'Punters club'!K8 -> 564.33 | AG12: =+AF12-AE12 -> -390.63 | AH12: =(AF12-AE12)/AE12 -> -0.40905378
B13: R10 | O13: 25 | P13: 0 | Q13: 25 | R13: 0 | S13: 25 | T13: 0 | Y13: =U13+S13+Q13+O13+M13+K13+I13+G13+E13+C13 -> 75 | Z13: =V13+T13+R13+P13+N13+L13+J13+H13+F13+D13 -> 0 | AA13: =AA12+Y13 -> 790 | AB13: =AB12+Z13 -> 179.54 | AC13: =AB13-AA13 -> -610.46 | AD13: ski | AE13: =+O29+'Punters 2021'!O27+'Punters 2020'!O27+'Punters club'!J9 -> 881.34 | AF13: =+P29+'Punters 2021'!P27+'Punters 2020'!P27+'Punters club'!K9 -> 218.25 | AG13: =+AF13-AE13 -> -663.09 | AH13: =(AF13-AE13)/AE13 -> -0.75236572
B14: R11 | C14: 25 | D14: 0 | E14: 25 | F14: 0 | Y14: =U14+S14+Q14+O14+M14+K14+I14+G14+E14+C14 -> 50 | Z14: =V14+T14+R14+P14+N14+L14+J14+H14+F14+D14 -> 0 | AA14: =AA13+Y14 -> 840 | AB14: =AB13+Z14 -> 179.54 | AC14: =AB14-AA14 -> -660.46 | AD14: cromps | AE14: =+Q29+'Punters 2021'!M27+'Punters 2020'!Q27+'Punters club'!J5 -> 883 | AF14: =+R29+'Punters 2021'!N27+'Punters 2020'!R27+'Punters club'!K5 -> 637.47 | AG14: =+AF14-AE14 -> -245.53 | AH14: =(AF14-AE14)/AE14 -> -0.27806342
B15: R12 | G15: 10 | H15: 0 | I15: 25 | J15: 322.48 | M15: 25 | N15: 0 | U15: 30 | V15: 46.25 | Y15: =U15+S15+Q15+O15+M15+K15+I15+G15+E15+C15 -> 90 | Z15: =V15+T15+R15+P15+N15+L15+J15+H15+F15+D15 -> 368.73 | AA15: =AA14+Y15 -> 930 | AB15: =AB14+Z15 -> 548.27 | AC15: =AB15-AA15 -> -381.73 | AD15: scott | AE15: =+S29+'Punters 2021'!C27+'Punters 2020'!C27+'Punters club'!J4 -> 892.7 | AF15: =+T29+'Punters 2021'!D27+'Punters 2020'!D27+'Punters club'!K4 -> 1461.09 | AG15: =+AF15-AE15 -> 568.39 | AH15: =(AF15-AE15)/AE15 -> 0.63670886
B16: R13 | G16: =5+2+2+2 -> 11 | H16: 34.1 | K16: =10+15 -> 25 | L16: 0 | O16: 25 | P16: 0 | Q16: =10+5+5+3+2+5-5 -> 25 | R16: 49.29 | S16: 25 | T16: 0 | U16: =5+5+10 -> 20 | V16: 0 | Y16: =U16+S16+Q16+O16+M16+K16+I16+G16+E16+C16 -> 131 | Z16: =V16+T16+R16+P16+N16+L16+J16+H16+F16+D16 -> 83.39 | AA16: =AA15+Y16 -> 1061 | AB16: =AB15+Z16 -> 631.66 | AC16: =AB16-AA16 -> -429.34 | AD16: simmo | AE16: =+U29 -> 200 | AF16: =+V29 -> 86.25 | AG16: =+AF16-AE16 -> -113.75 | AH16: =(AF16-AE16)/AE16 -> -0.56875
B17: R14 | C17: 25 | D17: 0 | E17: 25 | F17: 98.44 | G17: 25 | H17: 107.5 | Y17: =U17+S17+Q17+O17+M17+K17+I17+G17+E17+C17 -> 75 | Z17: =V17+T17+R17+P17+N17+L17+J17+H17+F17+D17 -> 205.94 | AA17: =AA16+Y17 -> 1136 | AB17: =AB16+Z17 -> 837.6 | AC17: =AB17-AA17 -> -298.4
B18: R15 | I18: =5+5+7.75+2.25+2.5+2.5 -> 25 | J18: 0.53 | K18: =10+5+10 -> 25 | L18: 0 | M18: =5+10+5 -> 20 | N18: 0 | U18: 15 | V18: 40 | Y18: =U18+S18+Q18+O18+M18+K18+I18+G18+E18+C18 -> 85 | Z18: =V18+T18+R18+P18+N18+L18+J18+H18+F18+D18 -> 40.53 | AA18: =AA17+Y18 -> 1221 | AB18: =AB17+Z18 -> 878.13 | AC18: =AB18-AA18 -> -342.87
B19: R16 | G19: 4 | H19: 0 | M19: 5 | N19: 0 | O19: 25 | P19: 217.61 | Q19: 25 | R19: 0 | S19: 25 | T19: 0 | Y19: =U19+S19+Q19+O19+M19+K19+I19+G19+E19+C19 -> 84 | Z19: =V19+T19+R19+P19+N19+L19+J19+H19+F19+D19 -> 217.61 | AA19: =AA18+Y19 -> 1305 | AB19: =AB18+Z19 -> 1095.74 | AC19: =AB19-AA19 -> -209.26
B20: R17 | C20: 25 | D20: 0 | E20: =10+8 -> 18 | F20: 0 | G20: =2+2+1+2+5+5+5+3 -> 25 | H20: 0 | U20: =5+5+5 -> 15 | V20: 0 | Y20: =U20+S20+Q20+O20+M20+K20+I20+G20+E20+C20 -> 83 | Z20: =V20+T20+R20+P20+N20+L20+J20+H20+F20+D20 -> 0 | AA20: =AA19+Y20 -> 1388 | AB20: =AB19+Z20 -> 1095.74 | AC20: =AB20-AA20 -> -292.26
B21: R18 | I21: =5+5+1+1+2+2+1+5+3 -> 25 | J21: 0 | K21: =5+10+5 -> 20 | L21: 46.25 | M21: =10+5+5 -> 20 | N21: 0 | U21: 5 | V21: 0 | Y21: =U21+S21+Q21+O21+M21+K21+I21+G21+E21+C21 -> 70 | Z21: =V21+T21+R21+P21+N21+L21+J21+H21+F21+D21 -> 46.25 | AA21: =AA20+Y21 -> 1458 | AB21: =AB20+Z21 -> 1141.99 | AC21: =AB21-AA21 -> -316.01
B22: R19 | M22: 5 | N22: 0 | O22: =5+5+2.5+2.5+2.5+2.5+5 -> 25 | Q22: =5+5+3+2+5+5 -> 25 | S22: =5+10+9.99 -> 24.99 | U22: =5+5+5 -> 15 | V22: 0 | Y22: =U22+S22+Q22+O22+M22+K22+I22+G22+E22+C22 -> 94.99 | Z22: =V22+T22+R22+P22+N22+L22+J22+H22+F22+D22 -> 0 | AA22: =AA21+Y22 -> 1552.99 | AB22: =AB21+Z22 -> 1141.99 | AC22: =AB22-AA22 -> -411
B23: R20 | C23: 25 | D23: 0 | E23: 27 | F23: 0 | Y23: =U23+S23+Q23+O23+M23+K23+I23+G23+E23+C23 -> 52 | Z23: =V23+T23+R23+P23+N23+L23+J23+H23+F23+D23 -> 0 | AA23: =AA22+Y23 -> 1604.99 | AB23: =AB22+Z23 -> 1141.99 | AC23: =AB23-AA23 -> -463
B24: R21 | E24: 5 | F24: 0 | G24: =5+3+5+7 -> 20 | H24: 259 | I24: =5+7.75+2.25+2.7+2.3+1+1+1+2 -> 25 | J24: 2.81 | K24: 30 | L24: 0 | M24: =2.5+2.5+2.5+2.5 -> 10 | N24: 0 | Y24: =U24+S24+Q24+O24+M24+K24+I24+G24+E24+C24 -> 90 | Z24: =V24+T24+R24+P24+N24+L24+J24+H24+F24+D24 -> 261.81 | AA24: =AA23+Y24 -> 1694.99 | AB24: =AB23+Z24 -> 1403.8 | AC24: =AB24-AA24 -> -291.19
B25: R22 | G25: 6 | H25: 0 | M25: 5 | N25: 0 | O25: =7.5+0.5+2+2.5+2.5+2.5+2.5+5 -> 25 | P25: 0 | Q25: =5+5+10+5 -> 25 | R25: 0 | S25: =1+4+5+5+10+10 -> 35 | T25: 0 | U25: 5 | Y25: =U25+S25+Q25+O25+M25+K25+I25+G25+E25+C25 -> 101 | Z25: =V25+T25+R25+P25+N25+L25+J25+H25+F25+D25 -> 0 | AA25: =AA24+Y25 -> 1795.99 | AB25: =AB24+Z25 -> 1403.8 | AC25: =AB25-AA25 -> -392.19
B26: R23 | C26: 15 | D26: 7.75 | E26: 15 | F26: 16 | G26: =7+7 -> 14 | H26: 0 | I26: 15 | J26: 0 | K26: 15 | L26: 0 | M26: =10+10 -> 20 | O26: 15 | P26: 0 | Q26: =10+5 -> 15 | S26: 5.01 | T26: 0 | U26: =10+10+10+5+5+5+5 -> 50 | Y26: =U26+S26+Q26+O26+M26+K26+I26+G26+E26+C26 -> 179.01 | Z26: =V26+T26+R26+P26+N26+L26+J26+H26+F26+D26 -> 23.75 | AA26: =AA24+Y26 -> 1874 | AB26: =AB24+Z26 -> 1427.55 | AC26: =AB26-AA26 -> -446.45
B27: Finals | E27: 10 | F27: 0 | G27: =5+5 -> 10 | H27: 0 | I27: 10 | J27: 0 | M27: 5 | N27: 0 | O27: 10 | P27: 0 | Q27: 10 | R27: 0 | S27: 10 | T27: 0 | U27: =5+5+5+5 -> 20 | W27: 0 | X27: 93.78 | Y27: =U27+S27+Q27+O27+M27+K27+I27+G27+E27+C27 -> 85 | Z27: =V27+T27+R27+P27+N27+L27+J27+H27+F27+D27+X27 -> 93.78 | AA27: =AA25+Y27 -> 1880.99 | AB27: =AB25+Z27 -> 1497.58 | AC27: =AB27-AA27 -> -383.41
B28: Glory | W28: 461.33 | X28: 1476.26 | Y28: =U28+S28+Q28+O28+M28+K28+I28+G28+E28+C28+W28 -> 461.33 | Z28: =V28+T28+R28+P28+N28+L28+J28+H28+F28+D28+X28 -> 1476.26 | AA28: =AA25+Y28 -> 2257.32 | AB28: =AB25+Z28 -> 2880.06 | AC28: =AB28-AA28 -> 622.74
B29: total | C29: =SUM(C4:C28) -> 200 | D29: =SUM(D4:D28) -> 7.75 | E29: =SUM(E4:E28) -> 210 | F29: =SUM(F4:F28) -> 222.44 | G29: =SUM(G4:G28) -> 210 | H29: =SUM(H4:H28) -> 400.6 | I29: =SUM(I4:I28) -> 210 | J29: =SUM(J4:J28) -> 325.82 | ... Z29: =SUM(Z4:Z28) -> 2997.59
D30: =(D29-C29)/C29 -> -0.96125 | F30: =(F29-E29)/E29 -> 0.059238095 | H30: =(H29-G29)/G29 -> 0.90761905 | J30: =(J29-I29)/I29 -> 0.55152381 | L30: =(L29-K29)/K29 -> -0.76875 | N30: =(N29-M29)/M29 -> -1 | P30: =(P29-O29)/O29 -> 0.036238095 | R30: =(R29-Q29)/Q29 -> -0.42461905 | T30: =(T29-S29)/S29 -> -1
F31: TOTAL INVESTMENT | I31: =C29+E29+G29+I29+K29+M29+O29+Q29+S29+U29+W29 -> 2521.33
G32: TOTAL RETURNS | I32: =+D29+F29+H29+J29+L29+N29+P29+R29+T29+V29+X29 -> 2997.59
I33: =I32-I31 -> 476.26
C34: =C29+E29+G29 -> 620 | D34: =D29+F29+H29 -> 630.79 | E34: =D34-C34 -> 10.79 | I34: =I29+K29+M29 -> 610 | J34: =J29+L29+N29 -> 372.07 | K34: =J34-I34 -> -237.93 | O34: =O29+Q29+S29 -> 630 | P34: =P29+R29+T29 -> 338.44 | Q34: =P34-O34 -> -291.56
G35: initial | I35: 2000
G36: BALANCE OF ACC | I36: =I35+I33 -> 2476.26
C40: =C29+E29+G29 -> 620 | D40: =D29+F29+H29 -> 630.79 | I40: =I29+K29+M29 -> 610 | J40: =J29+L29+N29 -> 372.07 | O40: =O29+Q29+S29 -> 630 | P40: =P29+R29+T29 -> 338.44
D41: =D40-C40 -> 10.79 | J41: =J40-I40 -> -237.93 | P41: =P40-O40 -> -291.56

Sheet Punters 2023
C2: B. SPICER | E2: B. TURNOR | G2: J. VELLIOU | I2: P. BLAKEY | K2: S. BAMFORD | M2: K. HORNSEY | O2: B. RAFFAELE | Q2: B. JASKOLA | S2: D. MILEVSKI | U2: S. CAPOZZI | W2: Group BET | Y2: WEEKLY TOTAL
B3: ROUND | C3: INVESTMENT | D3: RETURN | E3: INVESTMENT | F3: RETURN | G3: INVESTMENT | H3: RETURN | I3: INVESTMENT | J3: RETURN | K3: INVESTMENT | L3: RETURN | M3: INVESTMENT | N3: RETURN | O3: INVESTMENT | P3: RETURN | Q3: INVESTMENT | R3: RETURN | S3: INVESTMENT | T3: RETURN | U3: INVESTMENT | V3: RETURN | W3: INVESTMENT | X3: RETURN | Y3: INVESTMENT | Z3: RETURN | AA3: INVESTMENT | AB3: RETURN | AC3: NET RESULT AT TIME
B4: R1 | C4: 5 | D4: 0 | E4: 15 | F4: 0 | G4: 12.5 | H4: 0 | I4: =5+2.5+2.5 -> 10 | J4: 0 | K4: 15 | L4: 0 | M4: 15 | N4: 0 | O4: 15 | P4: 0 | Q4: 15 | R4: 0 | S4: =5+5+5 -> 15 | T4: 0 | U4: 15 | V4: 0 | Y4: =U4+S4+Q4+O4+M4+K4+I4+G4+E4+C4 -> 132.5 | Z4: =V4+T4+R4+P4+N4+L4+J4+H4+F4+D4 -> 0 | AA4: =Y4 -> 132.5 | AB4: =Z4 -> 0 | AC4: =AB4-AA4 -> -132.5
B5: R2 | C5: =5+5+10+10 -> 30 | D5: 26.8 | E5: =10+10+10 -> 30 | F5: 0 | G5: 32.5 | H5: 0 | I5: =10+5+5+5+3+3+4 -> 35 | J5: 0 | Y5: =U5+S5+Q5+O5+M5+K5+I5+G5+E5+C5 -> 127.5 | Z5: =V5+T5+R5+P5+N5+L5+J5+H5+F5+D5 -> 26.8 | AA5: =AA4+Y5 -> 260 | AB5: =AB4+Z5 -> 26.8 | AC5: =AB5-AA5 -> -233.2
B6: R3 | K6: =10+10+5+0 -> 25 | L6: 0 | M6: =10+5+5+5+10 -> 35 | N6: 0 | O6: =5+5+10+5+5 -> 30 | P6: 0 | Y6: =U6+S6+Q6+O6+M6+K6+I6+G6+E6+C6 -> 90 | Z6: =V6+T6+R6+P6+N6+L6+J6+H6+F6+D6 -> 0 | AA6: =AA5+Y6 -> 350 | AB6: =AB5+Z6 -> 26.8 | AC6: =AB6-AA6 -> -323.2 | AE6: bets | AF6: return | AG6: summary | AH6: percentage
B7: R4 | Q7: 30 | R7: 0 | S7: =5+10+5+5+5 -> 30 | T7: 167.5 | U7: =5+5+5+1+3+1+3+5 -> 28 | V7: 0 | Y7: =U7+S7+Q7+O7+M7+K7+I7+G7+E7+C7 -> 88 | Z7: =V7+T7+R7+P7+N7+L7+J7+H7+F7+D7 -> 167.5 | AA7: =AA6+Y7 -> 438 | AB7: =AB6+Z7 -> 194.3 | AC7: =AB7-AA7 -> -243.7 | AD7: moose | AE7: =+G29+'Punters 2021'!Q27+'Punters 2020'!M27+'Punters club'!J6+'Punters 2022'!C29 -> 1003 | AF7: =+H29+'Punters 2021'!R27+'Punters 2020'!N27+'Punters club'!K6+'Punters 2022'!D29 -> 534 | AG7: =+AF7-AE7 -> -469 | AH7: =(AF7-AE7)/AE7 -> -0.46759721
B8: R5 | C8: =10+5+5+10+10 -> 40 | D8: =54.19+0.01 -> 54.2 | E8: 30 | F8: 0 | G8: =10+10 -> 20 | H8: 0 | I8: 23 | J8: 0 | Y8: =U8+S8+Q8+O8+M8+K8+I8+G8+E8+C8 -> 113 | Z8: =V8+T8+R8+P8+N8+L8+J8+H8+F8+D8 -> 54.2 | AA8: =AA7+Y8 -> 551 | AB8: =AB7+Z8 -> 248.5 | AC8: =AB8-AA8 -> -302.5 | AD8: bt | AE8: =+E29+'Punters 2021'!I27+'Punters 2020'!G27+'Punters club'!J7+'Punters 2022'!E29 -> 1163 | AF8: =+F29+'Punters 2021'!J27+'Punters 2020'!H27+'Punters club'!K7+'Punters 2022'!F29 -> 1019.77 | AG8: =+AF8-AE8 -> -143.23 | AH8: =(AF8-AE8)/AE8 -> -0.12315563
B9: R6 | I9: 5 | J9: 0 | K9: 30 | L9: 0 | M9: 30 | N9: 0 | O9: 30 | P9: 0 | Y9: =U9+S9+Q9+O9+M9+K9+I9+G9+E9+C9 -> 95 | Z9: =V9+T9+R9+P9+N9+L9+J9+H9+F9+D9 -> 0 | AA9: =AA8+Y9 -> 646 | AB9: =AB8+Z9 -> 248.5 | AC9: =AB9-AA9 -> -397.5 | AD9: blakey | AE9: =+I29+'Punters 2021'!K27+'Punters 2020'!E27+'Punters club'!J11+'Punters 2022'!G29 -> 1136.48 | AF9: =+J29+'Punters 2021'!L27+'Punters 2020'!F27+'Punters club'!K11+'Punters 2022'!H29 -> 961.4 | AG9: =+AF9-AE9 -> -175.08 | AH9: =(AF9-AE9)/AE9 -> -0.15405462
B10: R7 | Q10: 30 | R10: 0 | S10: 30 | T10: 0 | Y10: =U10+S10+Q10+O10+M10+K10+I10+G10+E10+C10 -> 60 | Z10: =V10+T10+R10+P10+N10+L10+J10+H10+F10+D10 -> 0 | AA10: =AA9+Y10 -> 706 | AB10: =AB9+Z10 -> 248.5 | AC10: =AB10-AA10 -> -457.5 | AD10: fake | AE10: =+Q29+'Punters 2021'!G27+'Punters 2020'!I27+'Punters club'!J10+'Punters 2022'!I29 -> 1139.9 | AF10: =+R29+'Punters 2021'!H27+'Punters 2020'!J27+'Punters club'!K10+'Punters 2022'!J29 -> 1516.45 | AG10: =+AF10-AE10 -> 376.55 | AH10: =(AF10-AE10)/AE10 -> 0.33033599
B11: R8 | C11: 30 | D11: 0 | E11: 30 | F11: 0 | G11: 30 | H11: 0 | I11: 32 | J11: 0 | U11: 18 | V11: 0 | Y11: =U11+S11+Q11+O11+M11+K11+I11+G11+E11+C11 -> 140 | Z11: =V11+T11+R11+P11+N11+L11+J11+H11+F11+D11 -> 0 | AA11: =AA10+Y11 -> 846 | AB11: =AB10+Z11 -> 248.5 | AC11: =AB11-AA11 -> -597.5 | AD11: kane | AE11: =+M29+'Punters 2021'!E27+'Punters 2020'!K27+'Punters 2022'!K29 -> 868 | AF11: =+N29+'Punters 2021'!F27+'Punters 2020'!L27+'Punters 2022'!L29 -> 58.25 | AG11: =+AF11-AE11 -> -809.75 | AH11: =(AF11-AE11)/AE11 -> -0.93289171
B12: R9 | K12: 35 | L12: 0 | O12: 30 | P12: 0 | Y12: =U12+S12+Q12+O12+M12+K12+I12+G12+E12+C12 -> 65 | Z12: =V12+T12+R12+P12+N12+L12+J12+H12+F12+D12 -> 0 | AA12: =AA11+Y12 -> 911 | AB12: =AB11+Z12 -> 248.5 | AC12: =AB12-AA12 -> -662.5 | AD12: spicer | AE12: =+C29+'Punters 2021'!S27+'Punters 2020'!S27+'Punters club'!J8+'Punters 2022'!M29 -> 1194.96 | AF12: =+D29+'Punters 2021'!T27+'Punters 2020'!T27+'Punters club'!K8+'Punters 2022'!N29 -> 844.41 | AG12: =+AF12-AE12 -> -350.55 | AH12: =(AF12-AE12)/AE12 -> -0.2933571
B13: R10 | M13: 20 | N13: 0 | Q13: 25.5 | R13: 0 | S13: 30 | T13: 16.14 | Y13: =U13+S13+Q13+O13+M13+K13+I13+G13+E13+C13 -> 75.5 | Z13: =V13+T13+R13+P13+N13+L13+J13+H13+F13+D13 -> 16.14 | AA13: =AA12+Y13 -> 986.5 | AB13: =AB12+Z13 -> 264.64 | AC13: =AB13-AA13 -> -721.86 | AD13: ski | AE13: =+S29+'Punters 2021'!O27+'Punters 2020'!O27+'Punters club'!J9+'Punters 2022'!O29 -> 1121.34 | AF13: =+T29+'Punters 2021'!P27+'Punters 2020'!P27+'Punters club'!K9+'Punters 2022'!P29 -> 498.08 | AG13: =+AF13-AE13 -> -623.26 | AH13: =(AF13-AE13)/AE13 -> -0.55581715
B14: R11 | C14: 15 | D14: 195 | E14: 30 | F14: 0 | G14: 20 | H14: 0 | I14: 30 | J14: 0 | Y14: =U14+S14+Q14+O14+M14+K14+I14+G14+E14+C14 -> 95 | Z14: =V14+T14+R14+P14+N14+L14+J14+H14+F14+D14 -> 195 | AA14: =AA13+Y14 -> 1081.5 | AB14: =AB13+Z14 -> 459.64 | AC14: =AB14-AA14 -> -621.86 | AD14: cromps | AE14: =+O29+'Punters 2021'!M27+'Punters 2020'!Q27+'Punters club'!J5+'Punters 2022'!Q29 -> 1123 | AF14: =+P29+'Punters 2021'!N27+'Punters 2020'!R27+'Punters club'!K5+'Punters 2022'!R29 -> 637.47 | AG14: =+AF14-AE14 -> -485.53 | AH14: =(AF14-AE14)/AE14 -> -0.43235085
B15: R12 | K15: 30 | L15: 0 | M15: 10 | N15: 0 | O15: 30 | P15: 0 | Y15: =U15+S15+Q15+O15+M15+K15+I15+G15+E15+C15 -> 70 | Z15: =V15+T15+R15+P15+N15+L15+J15+H15+F15+D15 -> 0 | AA15: =AA14+Y15 -> 1151.5 | AB15: =AB14+Z15 -> 459.64 | AC15: =AB15-AA15 -> -691.86 | AD15: scott | AE15: =+K29+'Punters 2021'!C27+'Punters 2020'!C27+'Punters club'!J4+'Punters 2022'!S29 -> 1132.7 | AF15: =+L29+'Punters 2021'!D27+'Punters 2020'!D27+'Punters club'!K4+'Punters 2022'!T29 -> 1461.09 | AG15: =+AF15-AE15 -> 328.39 | AH15: =(AF15-AE15)/AE15 -> 0.2899179
B16: R13 | Q16: 30 | R16: 0 | S16: 30 | T16: 0 | U16: 19 | V16: 0 | Y16: =U16+S16+Q16+O16+M16+K16+I16+G16+E16+C16 -> 79 | Z16: =V16+T16+R16+P16+N16+L16+J16+H16+F16+D16 -> 0 | AA16: =AA15+Y16 -> 1230.5 | AB16: =AB15+Z16 -> 459.64 | AC16: =AB16-AA16 -> -770.86 | AD16: simmo | AE16: =+U29+'Punters 2022'!U29 -> 427 | AF16: =+V29+'Punters 2022'!V29 -> 151.25 | AG16: =+AF16-AE16 -> -275.75 | AH16: =(AF16-AE16)/AE16 -> -0.64578454
B17: R14 | C17: 30 | D17: 0 | E17: 30 | F17: 0 | G17: 20 | H17: 0 | I17: 30 | J17: 0 | U17: 22 | V17: 0 | Y17: =U17+S17+Q17+O17+M17+K17+I17+G17+E17+C17 -> 132 | Z17: =V17+T17+R17+P17+N17+L17+J17+H17+F17+D17 -> 0 | AA17: =AA16+Y17 -> 1362.5 | AB17: =AB16+Z17 -> 459.64 | AC17: =AB17-AA17 -> -902.86
B18: R15 | K18: 30 | L18: 0 | M18: 30 | N18: 0 | O18: 30 | P18: 0 | Y18: =U18+S18+Q18+O18+M18+K18+I18+G18+E18+C18 -> 90 | Z18: =V18+T18+R18+P18+N18+L18+J18+H18+F18+D18 -> 0 | AA18: =AA17+Y18 -> 1452.5 | AB18: =AB17+Z18 -> 459.64 | AC18: =AB18-AA18 -> -992.86
B19: R16 | Q19: 30 | R19: 0 | S19: 30 | T19: 63.39 | U19: =5+5+5 -> 15 | V19: 0 | Y19: =U19+S19+Q19+O19+M19+K19+I19+G19+E19+C19 -> 75 | Z19: =V19+T19+R19+P19+N19+L19+J19+H19+F19+D19 -> 63.39 | AA19: =AA18+Y19 -> 1527.5 | AB19: =AB18+Z19 -> 523.03 | AC19: =AB19-AA19 -> -1004.47
B20: R17 | C20: 30 | D20: 0 | E20: 30 | F20: 0 | G20: 30 | H20: 0 | I20: 30 | J20: 0 | Y20: =U20+S20+Q20+O20+M20+K20+I20+G20+E20+C20 -> 120 | Z20: =V20+T20+R20+P20+N20+L20+J20+H20+F20+D20 -> 0 | AA20: =AA19+Y20 -> 1647.5 | AB20: =AB19+Z20 -> 523.03 | AC20: =AB20-AA20 -> -1124.47
B21: R18 | G21: 20 | H21: 0 | K21: 30 | L21: 0 | M21: 10 | N21: 0 | O21: 30 | P21: 0 | Y21: =U21+S21+Q21+O21+M21+K21+I21+G21+E21+C21 -> 90 | Z21: =V21+T21+R21+P21+N21+L21+J21+H21+F21+D21 -> 0 | AA21: =AA20+Y21 -> 1737.5 | AB21: =AB20+Z21 -> 523.03 | AC21: =AB21-AA21 -> -1214.47
B22: R19 | Q22: 34.5 | R22: 30 | S22: 30 | T22: 0 | U22: =30+20 -> 50 | V22: 25 | Y22: =U22+S22+Q22+O22+M22+K22+I22+G22+E22+C22 -> 114.5 | Z22: =V22+T22+R22+P22+N22+L22+J22+H22+F22+D22 -> 55 | AA22: =AA21+Y22 -> 1852 | AB22: =AB21+Z22 -> 578.03 | AC22: =AB22-AA22 -> -1273.97
B23: R20 | C23: =10+5+5+10 -> 30 | D23: 0 | E23: 30 | F23: 0 | G23: =10+10+10 -> 30 | H23: 0 | I23: =10+5+5+5 -> 25 | J23: 0 | Y23: =U23+S23+Q23+O23+M23+K23+I23+G23+E23+C23 -> 115 | Z23: =V23+T23+R23+P23+N23+L23+J23+H23+F23+D23 -> 0 | AA23: =AA22+Y23 -> 1967 | AB23: =AB22+Z23 -> 578.03 | AC23: =AB23-AA23 -> -1388.97
B24: R21 | K24: 30 | L24: 0 | M24: =5+10+10+10 -> 35 | N24: 0 | O24: 30 | P24: 0 | Y24: =U24+S24+Q24+O24+M24+K24+I24+G24+E24+C24 -> 95 | Z24: =V24+T24+R24+P24+N24+L24+J24+H24+F24+D24 -> 0 | AA24: =AA23+Y24 -> 2062 | AB24: =AB23+Z24 -> 578.03 | AC24: =AB24-AA24 -> -1483.97
B25: R22 | Q25: 30 | R25: =0.41+26.14 -> 26.55 | S25: 30 | T25: 0 | U25: =10+5+5+10+10+5 -> 45 | V25: 40 | Y25: =U25+S25+Q25+O25+M25+K25+I25+G25+E25+C25 -> 105 | Z25: =V25+T25+R25+P25+N25+L25+J25+H25+F25+D25 -> 66.55 | AA25: =AA24+Y25 -> 2167 | AB25: =AB24+Z25 -> 644.58 | AC25: =AB25-AA25 -> -1522.42
B26: R23 | C26: 29 | D26: 4.08 | E26: 15 | F26: 0 | I26: 10 | J26: 0 | K26: 15 | L26: 0 | M26: 30 | N26: 0 | O26: 15 | P26: 0 | Q26: 15 | R26: 0 | S26: 15 | T26: 32.8 | U26: =5+5+5 -> 15 | V26: 0 | Y26: =U26+S26+Q26+O26+M26+K26+I26+G26+E26+C26 -> 159 | Z26: =V26+T26+R26+P26+N26+L26+J26+H26+F26+D26 -> 36.88 | AA26: =AA25+Y26 -> 2326 | AB26: =AB25+Z26 -> 681.46 | AC26: =AB26-AA26 -> -1644.54
B27: R24 | C27: 1 | D27: 0 | I27: 10 | J27: 0 | M27: 20 | N27: 0 | W27: 105.73 | X27: 322.79 | Y27: =U27+S27+Q27+O27+M27+K27+I27+G27+E27+C27+W27 -> 136.73 | Z27: =V27+T27+R27+P27+N27+L27+J27+H27+F27+D27+X27 -> 322.79
B28: Finals | Y28: =U28+S28+Q28+O28+M28+K28+I28+G28+E28+C28 -> 0 | Z28: =V28+T28+R28+P28+N28+L28+J28+H28+F28+D28+X28 -> 0
B29: total | C29: =SUM(C4:C28) -> 240 | D29: =SUM(D4:D28) -> 280.08 | E29: =SUM(E4:E28) -> 240 | F29: =SUM(F4:F28) -> 0 | G29: =SUM(G4:G28) -> 215 | H29: =SUM(H4:H28) -> 0 | I29: =SUM(I4:I28) -> 240 | J29: =SUM(J4:J28) -> 0 | ... Z29: =SUM(Z4:Z28) -> 1004.25
D30: =(D29-C29)/C29 -> 0.167 | F30: =(F29-E29)/E29 -> -1 | H30: =(H29-G29)/G29 -> -1 | J30: =(J29-I29)/I29 -> -1 | L30: =(L29-K29)/K29 -> -1 | N30: =(N29-M29)/M29 -> -1 | P30: =(P29-O29)/O29 -> -1 | R30: =(R29-Q29)/Q29 -> -0.764375 | T30: =(T29-S29)/S29 -> 0.16595833 | V30: =(V29-U29)/U29 -> -0.71365639
F31: TOTAL INVESTMENT | I31: =C29+E29+G29+I29+K29+M29+O29+Q29+S29+U29+W29 -> 2462.73
G32: TOTAL RETURNS | I32: =+D29+F29+H29+J29+L29+N29+P29+R29+T29+V29+X29 -> 1004.25
I33: =I32-I31 -> -1458.48 | Y33: =2167+183+5*10 -> 2400
C34: =C29+E29+G29+I29 -> 935 | D34: =D29+F29+H29+J29 -> 280.08 | E34: =D34-C34 -> -654.92 | I34: =O29+K29+M29 -> 715 | J34: =P29+L29+N29 -> 0 | K34: =J34-I34 -> -715 | O34: =U29+Q29+S29 -> 707 | P34: =V29+R29+T29 -> 401.38 | Q34: =P34-O34 -> -305.62 | Y34: =15*10 -> 150
D35: =(D34-C34)/C34 -> -0.7004492 | J35: =(J34-I34)/I34 -> -1 | P35: =(P34-O34)/O34 -> -0.43227723
G36: initial | I36: {=2000+'Punters 2022'!I36:J36} -> 4476.26 | J36: 2000
G37: Deductions 25/7 | J37: =-269.5*10 -> -2695
G38: BALANCE OF ACC | I38: =I36+I33+J37 -> 322.78
C40: 1 | E40: 0 | G40: =10+15 -> 25 | I40: 10 | K40: 0 | M40: 25 | O40: 0 | Q40: 0 | S40: 0 | U40: 13 | X40: R23 left to spend | Y40: =30+15+25+20+15+55+15+15+15+28 -> 233
V41: =3260-720 -> 2540
C42: =C29+E29+G29+I29 -> 935 | D42: =D29+F29+H29+J29 -> 280.08 | I42: =O29+K29+M29 -> 715 | J42: =P29+L29+N29 -> 0 | O42: =U29+Q29+S29 -> 707 | P42: =V29+R29+T29 -> 401.38
...

Sheet Punters 2024
C2: B.JASKOLA | E2: J.VELLIOU | G2: S.CAPOZZI | I2: K.HORNSEY | K2: B.TURNOR | M2: P.BLAKEY | O2: S.BAMFORD | Q2: B.RAFFAELE | S2: D. MILEVSKI | U2: B.SPICER | W2: Group BET | Y2: WEEKLY TOTAL
B3: ROUND | C3: INVESTMENT | D3: RETURN | E3: INVESTMENT | F3: RETURN | G3: INVESTMENT | H3: RETURN | I3: INVESTMENT | J3: RETURN | K3: INVESTMENT | L3: RETURN | M3: INVESTMENT | N3: RETURN | O3: INVESTMENT | P3: RETURN | Q3: INVESTMENT | R3: RETURN | S3: INVESTMENT | T3: RETURN | U3: INVESTMENT | V3: RETURN | W3: INVESTMENT | X3: RETURN | Y3: INVESTMENT | Z3: RETURN | AA3: INVESTMENT | AB3: RETURN | AC3: NET RESULT AT TIME
B4: OR | Y4: =U4+S4+Q4+O4+M4+K4+I4+G4+E4+C4 -> 0 | Z4: =V4+T4+R4+P4+N4+L4+J4+H4+F4+D4 -> 0 | AA4: =Y4 -> 0 | AB4: =Z4 -> 0 | AC4: =AB4-AA4 -> 0
B5: R1 | C5: 25 | D5: 0 | E5: 10 | F5: 0 | G5: =3+5+2+5+5+3 -> 23 | H5: 0 | I5: 20 | J5: 0 | K5: 25 | L5: 0 | M5: 25 | N5: 47.5 | O5: 25 | P5: 235 | Q5: 25 | R5: 0 | S5: 25 | T5: 0 | U5: 20 | V5: 0 | Y5: =U5+S5+Q5+O5+M5+K5+I5+G5+E5+C5 -> 223 | Z5: =V5+T5+R5+P5+N5+L5+J5+H5+F5+D5 -> 282.5 | AA5: =AA4+Y5 -> 223 | AB5: =AB4+Z5 -> 282.5 | AC5: =AB5-AA5 -> 59.5
B6: R2 | C6: 25 | D6: 0 | E6: 40 | F6: 0 | G6: 25 | H6: 0 | I6: 30 | J6: 0 | U6: 5 | V6: 0 | Y6: =U6+S6+Q6+O6+M6+K6+I6+G6+E6+C6 -> 125 | Z6: =V6+T6+R6+P6+N6+L6+J6+H6+F6+D6 -> 0 | AA6: =AA5+Y6 -> 348 | AB6: =AB5+Z6 -> 282.5 | AC6: =AB6-AA6 -> -65.5 | AE6: bets | AF6: return | AG6: summary | AH6: percentage
B7: R3 | K7: 25 | L7: 0 | M7: 30 | N7: 0 | O7: 25 | P7: 0 | Y7: =U7+S7+Q7+O7+M7+K7+I7+G7+E7+C7 -> 80 | Z7: =V7+T7+R7+P7+N7+L7+J7+H7+F7+D7 -> 0 | AA7: =AA6+Y7 -> 428 | AB7: =AB6+Z7 -> 282.5 | AC7: =AB7-AA7 -> -145.5 | AD7: moose | AE7: =+E29+'Punters 2023'!AE7 -> 1208 | AF7: =+F29+'Punters 2023'!AF7 -> 542.6 | AG7: =+AF7-AE7 -> -665.4 | AH7: =(AF7-AE7)/AE7 -> -0.55082781
B8: R4 | Q8: 30 | R8: 0 | S8: 30 | T8: 0 | U8: 10 | V8: 0 | Y8: =U8+S8+Q8+O8+M8+K8+I8+G8+E8+C8 -> 70 | Z8: =V8+T8+R8+P8+N8+L8+J8+H8+F8+D8 -> 0 | AA8: =AA7+Y8 -> 498 | AB8: =AB7+Z8 -> 282.5 | AC8: =AB8-AA8 -> -215.5 | AD8: bt | AE8: =+K29+'Punters 2023'!AE8 -> 1388 | AF8: =+L29+'Punters 2023'!AF8 -> 1138.52 | AG8: =+AF8-AE8 -> -249.48 | AH8: =(AF8-AE8)/AE8 -> -0.17974063
B9: R5 | C9: 25 | D9: 0 | E9: 25 | F9: 0 | G9: 25 | H9: 0 | I9: 10 | J9: 0 | Y9: =U9+S9+Q9+O9+M9+K9+I9+G9+E9+C9 -> 85 | Z9: =V9+T9+R9+P9+N9+L9+J9+H9+F9+D9 -> 0 | AA9: =AA8+Y9 -> 583 | AB9: =AB8+Z9 -> 282.5 | AC9: =AB9-AA9 -> -300.5 | AD9: blakey | AE9: =+M29+'Punters 2023'!AE9 -> 1366.48 | AF9: =N29+'Punters 2023'!AF9 -> 1093.9 | AG9: =+AF9-AE9 -> -272.58 | AH9: =(AF9-AE9)/AE9 -> -0.19947603
B10: R6 | K10: 25 | L10: 0 | M10: 20 | N10: 0 | O10: 25 | P10: 0 | Y10: =U10+S10+Q10+O10+M10+K10+I10+G10+E10+C10 -> 70 | Z10: =V10+T10+R10+P10+N10+L10+J10+H10+F10+D10 -> 0 | AA10: =AA9+Y10 -> 653 | AB10: =AB9+Z10 -> 282.5 | AC10: =AB10-AA10 -> -370.5 | AD10: fake | AE10: =+C29+'Punters 2023'!AE10 -> 1364.9 | AF10: =+D29+'Punters 2023'!AF10 -> 1516.45 | AG10: =+AF10-AE10 -> 151.55 | AH10: =(AF10-AE10)/AE10 -> 0.11103378
B11: R7 | Q11: 25 | R11: 0 | S11: 22.5 | T11: 0 | U11: 10 | V11: 0 | Y11: =U11+S11+Q11+O11+M11+K11+I11+G11+E11+C11 -> 57.5 | Z11: =V11+T11+R11+P11+N11+L11+J11+H11+F11+D11 -> 0 | AA11: =AA10+Y11 -> 710.5 | AB11: =AB10+Z11 -> 282.5 | AC11: =AB11-AA11 -> -428 | AD11: kane | AE11: =+I29+'Punters 2023'!AE11 -> 1073 | AF11: =+J29+'Punters 2023'!AF11 -> 98.25 | AG11: =+AF11-AE11 -> -974.75 | AH11: =(AF11-AE11)/AE11 -> -0.9084343
B12: R8 | C12: 25 | D12: 0 | E12: 20 | F12: 0 | G12: 25 | H12: 0 | I12: 20 | J12: 0 | Y12: =U12+S12+Q12+O12+M12+K12+I12+G12+E12+C12 -> 90 | Z12: =V12+T12+R12+P12+N12+L12+J12+H12+F12+D12 -> 0 | AA12: =AA11+Y12 -> 800.5 | AB12: =AB11+Z12 -> 282.5 | AC12: =AB12-AA12 -> -518 | AD12: spicer | AE12: =+U29+'Punters 2023'!AE12 -> 1384.96 | AF12: =+V29+'Punters 2023'!AF12 -> 890.66 | AG12: =+AF12-AE12 -> -494.3 | AH12: =(AF12-AE12)/AE12 -> -0.35690561
B13: R9 | K13: 25 | L13: 0 | M13: 25 | N13: 0 | O13: 25 | P13: 0 | Y13: =U13+S13+Q13+O13+M13+K13+I13+G13+E13+C13 -> 75 | Z13: =V13+T13+R13+P13+N13+L13+J13+H13+F13+D13 -> 0 | AA13: =AA12+Y13 -> 875.5 | AB13: =AB12+Z13 -> 282.5 | AC13: =AB13-AA13 -> -593 | AD13: ski | AE13: =+S29+'Punters 2023'!AE13 -> 1346.34 | AF13: =+T29+'Punters 2023'!AF13 -> 626.24 | AG13: =+AF13-AE13 -> -720.1 | AH13: =(AF13-AE13)/AE13 -> -0.53485747
B14: R10 | Q14: 25 | R14: 0 | S14: =10+7.5+5 -> 22.5 | T14: 105 | U14: 25 | V14: 0 | Y14: =U14+S14+Q14+O14+M14+K14+I14+G14+E14+C14 -> 72.5 | Z14: =V14+T14+R14+P14+N14+L14+J14+H14+F14+D14 -> 105 | AA14: =AA13+Y14 -> 948 | AB14: =AB13+Z14 -> 387.5 | AC14: =AB14-AA14 -> -560.5 | AD14: cromps | AE14: =+Q29+'Punters 2023'!AE14 -> 1353 | AF14: =+R29+'Punters 2023'!AF14 -> 637.47 | AG14: =+AF14-AE14 -> -715.53 | AH14: =(AF14-AE14)/AE14 -> -0.52884701
B15: R11 | C15: 25 | D15: 0 | E15: 20 | F15: 0 | G15: 20 | H15: 0 | I15: 25 | J15: 0 | Y15: =U15+S15+Q15+O15+M15+K15+I15+G15+E15+C15 -> 90 | Z15: =V15+T15+R15+P15+N15+L15+J15+H15+F15+D15 -> 0 | AA15: =AA14+Y15 -> 1038 | AB15: =AB14+Z15 -> 387.5 | AC15: =AB15-AA15 -> -650.5 | AD15: scott | AE15: =+O29+'Punters 2023'!AE15 -> 1362.7 | AF15: =+P29+'Punters 2023'!AF15 -> 1696.09 | AG15: =+AF15-AE15 -> 333.39 | AH15: =(AF15-AE15)/AE15 -> 0.244654
B16: R12 | K16: 25 | L16: 0 | M16: 25 | N16: 85 | O16: 25 | P16: 0 | Y16: =U16+S16+Q16+O16+M16+K16+I16+G16+E16+C16 -> 75 | Z16: =V16+T16+R16+P16+N16+L16+J16+H16+F16+D16 -> 85 | AA16: =AA15+Y16 -> 1113 | AB16: =AB15+Z16 -> 472.5 | AC16: =AB16-AA16 -> -640.5 | AD16: simmo | AE16: =+G29+'Punters 2023'!AE16 -> 620 | AF16: =+H29+'Punters 2023'!AF16 -> 151.25 | AG16: =+AF16-AE16 -> -468.75 | AH16: =(AF16-AE16)/AE16 -> -0.75604839
B17: R13 | Q17: 25 | R17: 0 | S17: 17.5 | T17: 0 | U17: 20 | V17: 0 | Y17: =U17+S17+Q17+O17+M17+K17+I17+G17+E17+C17 -> 62.5 | Z17: =V17+T17+R17+P17+N17+L17+J17+H17+F17+D17 -> 0 | AA17: =AA16+Y17 -> 1175.5 | AB17: =AB16+Z17 -> 472.5 | AC17: =AB17-AA17 -> -703
B18: R14 | C18: 25 | D18: 0 | E18: 20 | F18: 0 | G18: 25 | H18: 0 | I18: 25 | J18: 0 | S18: 7.5 | T18: 0 | Y18: =U18+S18+Q18+O18+M18+K18+I18+G18+E18+C18 -> 102.5 | Z18: =V18+T18+R18+P18+N18+L18+J18+H18+F18+D18 -> 0 | AA18: =AA17+Y18 -> 1278 | AB18: =AB17+Z18 -> 472.5 | AC18: =AB18-AA18 -> -805.5
B19: R15 | K19: 25 | L19: 53.75 | M19: 25 | N19: 0 | O19: 30 | P19: 0 | Y19: =U19+S19+Q19+O19+M19+K19+I19+G19+E19+C19 -> 80 | Z19: =V19+T19+R19+P19+N19+L19+J19+H19+F19+D19 -> 53.75 | AA19: =AA18+Y19 -> 1358 | AB19: =AB18+Z19 -> 526.25 | AC19: =AB19-AA19 -> -831.75
B20: R16 | Q20: 25 | R20: 0 | S20: 25 | T20: 0 | U20: 25 | V20: 46.25 | Y20: =U20+S20+Q20+O20+M20+K20+I20+G20+E20+C20 -> 75 | Z20: =V20+T20+R20+P20+N20+L20+J20+H20+F20+D20 -> 46.25 | AA20: =AA19+Y20 -> 1433 | AB20: =AB19+Z20 -> 572.5 | AC20: =AB20-AA20 -> -860.5
B21: R17 | C21: 25 | D21: 0 | E21: 25 | F21: 0 | I21: 25 | J21: 0 | Y21: =U21+S21+Q21+O21+M21+K21+I21+G21+E21+C21 -> 75 | Z21: =V21+T21+R21+P21+N21+L21+J21+H21+F21+D21 -> 0 | AA21: =AA20+Y21 -> 1508 | AB21: =AB20+Z21 -> 572.5 | AC21: =AB21-AA21 -> -935.5
B22: R18 | K22: 25 | L22: 65 | M22: 25 | N22: 0 | O22: 25 | P22: 0 | Y22: =U22+S22+Q22+O22+M22+K22+I22+G22+E22+C22 -> 75 | Z22: =V22+T22+R22+P22+N22+L22+J22+H22+F22+D22 -> 65 | AA22: =AA21+Y22 -> 1583 | AB22: =AB21+Z22 -> 637.5 | AC22: =AB22-AA22 -> -945.5
B23: R19 | Q23: 25 | R23: 0 | S23: 25 | T23: 0 | U23: 25 | V23: 0 | Y23: =U23+S23+Q23+O23+M23+K23+I23+G23+E23+C23 -> 75 | Z23: =V23+T23+R23+P23+N23+L23+J23+H23+F23+D23 -> 0 | AA23: =AA22+Y23 -> 1658 | AB23: =AB22+Z23 -> 637.5 | AC23: =AB23-AA23 -> -1020.5
B24: R20 | C24: 25 | D24: 0 | G24: 25 | H24: 0 | I24: 25 | J24: 0 | Y24: =U24+S24+Q24+O24+M24+K24+I24+G24+E24+C24 -> 75 | Z24: =V24+T24+R24+P24+N24+L24+J24+H24+F24+D24 -> 0 | AA24: =AA23+Y24 -> 1733 | AB24: =AB23+Z24 -> 637.5 | AC24: =AB24-AA24 -> -1095.5
B25: R21 | E25: 20 | F25: 0 | K25: 25 | L25: 0 | M25: 25 | N25: 0 | O25: 25 | P25: 0 | Y25: =U25+S25+Q25+O25+M25+K25+I25+G25+E25+C25 -> 95 | Z25: =V25+T25+R25+P25+N25+L25+J25+H25+F25+D25 -> 0 | AA25: =AA24+Y25 -> 1828 | AB25: =AB24+Z25 -> 637.5 | AC25: =AB25-AA25 -> -1190.5
B26: R22 | Q26: 25 | R26: 0 | S26: 25 | T26: 23.16 | U26: 25 | V26: 0 | Y26: =U26+S26+Q26+O26+M26+K26+I26+G26+E26+C26 -> 75 | Z26: =V26+T26+R26+P26+N26+L26+J26+H26+F26+D26 -> 23.16 | AA26: =AA25+Y26 -> 1903 | AB26: =AB25+Z26 -> 660.66 | AC26: =AB26-AA26 -> -1242.34
B27: R23 | C27: 25 | D27: 0 | K27: 25 | L27: 0 | Q27: 25 | R27: 0 | S27: 25 | T27: 0 | U27: 25 | V27: 0 | Y27: =U27+S27+Q27+O27+M27+K27+I27+G27+E27+C27+W27 -> 125 | Z27: =V27+T27+R27+P27+N27+L27+J27+H27+F27+D27+X27 -> 0 | AA27: =AA26+Y27 -> 2028 | AB27: =AB26+Z27 -> 660.66 | AC27: =AB27-AA27 -> -1367.34
B28: R24 | E28: 25 | F28: 8.6 | G28: 25 | H28: 0 | I28: 25 | J28: 40 | M28: 30 | N28: 0 | O28: 25 | P28: 0 | Y28: =U28+S28+Q28+O28+M28+K28+I28+G28+E28+C28 -> 130 | Z28: =V28+T28+R28+P28+N28+L28+J28+H28+F28+D28+X28 -> 48.6
B29: total | C29: =SUM(C4:C28) -> 225 | D29: =SUM(D4:D28) -> 0 | E29: =SUM(E4:E28) -> 205 | F29: =SUM(F4:F28) -> 8.6 | G29: =SUM(G4:G28) -> 193 | H29: =SUM(H4:H28) -> 0 | I29: =SUM(I4:I28) -> 205 | J29: =SUM(J4:J28) -> 40 | ... Z29: =SUM(Z4:Z28) -> 709.26
D30: =(D29-C29)/C29 -> -1 | F30: =(F29-E29)/E29 -> -0.95804878 | H30: =(H29-G29)/G29 -> -1 | J30: =(J29-I29)/I29 -> -0.80487805 | L30: =(L29-K29)/K29 -> -0.47222222 | N30: =(N29-M29)/M29 -> -0.42391304 | P30: =(P29-O29)/O29 -> 0.02173913 | R30: =(R29-Q29)/Q29 -> -1 | T30: =(T29-S29)/S29 -> -0.4304 | V30: =(V29-U29)/U29 -> -0.75657895
F31: TOTAL INVESTMENT | I31: =C29+E29+G29+I29+K29+M29+O29+Q29+S29+U29+W29 -> 2158
G32: TOTAL RETURNS | I32: =+D29+F29+H29+J29+L29+N29+P29+R29+T29+V29+X29 -> 709.26
I33: =I32-I31 -> -1448.74 | Y33: =2167+183+5*10 -> 2400
C34: =C29+E29+G29+I29 -> 828 | D34: =D29+F29+H29+J29 -> 48.6 | E34: =D34-C34 -> -779.4 | I34: =O29+K29+M29 -> 685 | J34: =P29+L29+N29 -> 486.25 | K34: =J34-I34 -> -198.75 | O34: =U29+Q29+S29 -> 645 | P34: =V29+R29+T29 -> 174.41 | Q34: =P34-O34 -> -470.59 | Y34: =15*10 -> 150
D35: =(D34-C34)/C34 -> -0.94130435 | J35: =(J34-I34)/I34 -> -0.29014599 | P35: =(P34-O34)/O34 -> -0.7295969
G36: initial | I36: =2000+1.59 -> 2001.59
G37: Deductions 25/7
G38: BALANCE OF ACC | I38: =I36+I33 -> 552.85
C42: =C29+E29+G29+I29 -> 828 | D42: =D29+F29+H29+J29 -> 48.6 | I42: =O29+K29+M29 -> 685 | J42: =P29+L29+N29 -> 486.25 | O42: =U29+Q29+S29 -> 645 | P42: =V29+R29+T29 -> 174.41
D43: =D42-C42 -> -779.4 | J43: =J42-I42 -> -198.75 | P43: =P42-O42 -> -470.59
V45: 1 leg losses @ 22nd August 2024
...

Sheet Punters 2025
C2: C.STARKIE | E2: J.VELLIOU | G2: C.PANO | I2: D.MILEVSKI | K2: B.TURNOR | M2: K.HORNSEY | O2: S.BAMFORD | Q2: B.RAFFAELE | S2: B.JASKOLA | U2: B.SPICER | W2: S.CAPOZZI | Y2: P.BLAKEY | AA2: Group BET | AC2: WEEKLY TOTAL
B3: ROUND | C3: INVESTMENT | D3: RETURN | E3: INVESTMENT | F3: RETURN | G3: INVESTMENT | H3: RETURN | I3: INVESTMENT | J3: RETURN | K3: INVESTMENT | L3: RETURN | M3: INVESTMENT | N3: RETURN | O3: INVESTMENT | P3: RETURN | Q3: INVESTMENT | R3: RETURN | S3: INVESTMENT | T3: RETURN | U3: INVESTMENT | V3: RETURN | W3: INVESTMENT | X3: RETURN | Y3: INVESTMENT | Z3: RETURN | AA3: INVESTMENT | AB3: RETURN | AC3: INVESTMENT | AD3: RETURN | AE3: INVESTMENT | AF3: RETURN | AG3: NET RESULT AT TIME
B4: OR | G4: 25 | H4: 0 | AC4: =U4+S4+Q4+O4+M4+K4+I4+G4+E4+C4+W4+Y4 -> 25 | AD4: =V4+T4+R4+P4+N4+L4+J4+H4+F4+D4 -> 0 | AE4: =AC4 -> 25 | AF4: =AD4 -> 0 | AG4: =AF4-AE4 -> -25
B5: R1 | C5: 25 | D5: 0 | E5: 25 | F5: 0 | I5: 25 | J5: 0 | K5: 25 | L5: 0 | M5: 20 | N5: 0 | O5: 25 | P5: 109.38 | Q5: 25 | R5: 0 | S5: 25 | T5: 190 | U5: 25 | V5: 0 | W5: 25 | X5: 0 | Y5: 25 | Z5: =54.38+45 -> 99.38 | AC5: =U5+S5+Q5+O5+M5+K5+I5+G5+E5+C5+W5+Y5 -> 270 | AD5: =V5+T5+R5+P5+N5+L5+J5+H5+F5+D5+X5+Z5 -> 398.76 | AE5: =AE4+AC5 -> 295 | AF5: =AF4+AD5 -> 398.76 | AG5: =AF5-AE5 -> 103.76
B6: R2 | C6: 20 | D6: 0 | E6: 20 | F6: 0 | G6: 25 | H6: 0 | I6: 25 | J6: 0 | M6: 5 | N6: 0 | AC6: =U6+S6+Q6+O6+M6+K6+I6+G6+E6+C6+W6+Y6 -> 95 | AD6: =V6+T6+R6+P6+N6+L6+J6+H6+F6+D6+X6+Z6 -> 0 | AE6: =AE5+AC6 -> 390 | AF6: =AF5+AD6 -> 398.76 | AG6: =AF6-AE6 -> 8.76 | AI6: bets | AJ6: return | AK6: summary | AL6: percentage
B7: R3 | E7: 5 | F7: 0 | K7: =10+7.5+5+2.5 -> 25 | L7: 0 | M7: =5+10+5 -> 20 | N7: 0 | O7: =5+5+5+5+5 -> 25 | P7: 0 | Q7: =5+10+5+5 -> 25 | R7: 0 | AC7: =U7+S7+Q7+O7+M7+K7+I7+G7+E7+C7+W7+Y7 -> 100 | AD7: =V7+T7+R7+P7+N7+L7+J7+H7+F7+D7+X7+Z7 -> 0 | AE7: =AE6+AC7 -> 490 | AF7: =AF6+AD7 -> 398.76 | AG7: =AF7-AE7 -> -91.24 | AH7: moose | AI7: =+E30+'Punters 2024'!AE7 -> 1428 | AJ7: =+F30+'Punters 2024'!AF7 -> 542.6 | AK7: =+AJ7-AI7 -> -885.4 | AL7: =(AJ7-AI7)/AI7 -> -0.62002801
B8: R4 | S8: 25 | T8: 0 | U8: 25 | V8: 0 | W8: 25 | X8: 0 | Y8: 25 | Z8: 1.65 | AC8: =U8+S8+Q8+O8+M8+K8+I8+G8+E8+C8+W8+Y8 -> 100 | AD8: =V8+T8+R8+P8+N8+L8+J8+H8+F8+D8+X8+Z8 -> 1.65 | AE8: =AE7+AC8 -> 590 | AF8: =AF7+AD8 -> 400.41 | AG8: =AF8-AE8 -> -189.59 | AH8: bt | AI8: =+K30+'Punters 2024'!AE8 -> 1613 | AJ8: =+L30+'Punters 2024'!AF8 -> 1138.52 | AK8: =+AJ8-AI8 -> -474.48 | AL8: =(AJ8-AI8)/AI8 -> -0.29415995
B9: R5 | C9: 30 | D9: 0 | E9: 25 | F9: 0 | G9: 25 | H9: 0 | I9: 25 | J9: 0 | AC9: =U9+S9+Q9+O9+M9+K9+I9+G9+E9+C9+W9+Y9 -> 105 | AD9: =V9+T9+R9+P9+N9+L9+J9+H9+F9+D9+X9+Z9 -> 0 | AE9: =AE8+AC9 -> 695 | AF9: =AF8+AD9 -> 400.41 | AG9: =AF9-AE9 -> -294.59 | AH9: blakey | AI9: =+Y30+'Punters 2024'!AE9 -> 1593.48 | AJ9: =Z30+'Punters 2024'!AF9 -> 1278.68 | AK9: =+AJ9-AI9 -> -314.8 | AL9: =(AJ9-AI9)/AI9 -> -0.19755504
B10: R6 | K10: 25 | L10: 0 | M10: =5+10+5+10 -> 30 | N10: 0 | O10: 25 | P10: 0 | Q10: 25 | R10: 0 | AC10: =U10+S10+Q10+O10+M10+K10+I10+G10+E10+C10+W10+Y10 -> 105 | AD10: =V10+T10+R10+P10+N10+L10+J10+H10+F10+D10+X10+Z10 -> 0 | AE10: =AE9+AC10 -> 800 | AF10: =AF9+AD10 -> 400.41 | AG10: =AF10-AE10 -> -399.59 | AH10: fake | AI10: =+S30+'Punters 2024'!AE10 -> 1589.9 | AJ10: =+T30+'Punters 2024'!AF10 -> 1785.06 | AK10: =+AJ10-AI10 -> 195.16 | AL10: =(AJ10-AI10)/AI10 -> 0.12274986
B11: R7 | S11: 25 | T11: 78.61 | U11: 25 | V11: 0 | W11: 25 | X11: =33.75+32.5 -> 66.25 | Y11: 25 | Z11: 83.75 | AC11: =U11+S11+Q11+O11+M11+K11+I11+G11+E11+C11+W11+Y11 -> 100 | AD11: =V11+T11+R11+P11+N11+L11+J11+H11+F11+D11+X11+Z11 -> 228.61 | AE11: =AE10+AC11 -> 900 | AF11: =AF10+AD11 -> 629.02 | AG11: =AF11-AE11 -> -270.98 | AH11: kane | AI11: =+M30+'Punters 2024'!AE11 -> 1293 | AJ11: =+N30+'Punters 2024'!AF11 -> 166.25 | AK11: =+AJ11-AI11 -> -1126.75 | AL11: =(AJ11-AI11)/AI11 -> -0.87142305
B12: R8 | C12: 25 | D12: 80 | E12: 25 | F12: 0 | G12: 25 | H12: 0 | AC12: =U12+S12+Q12+O12+M12+K12+I12+G12+E12+C12+W12+Y12 -> 75 | AD12: =V12+T12+R12+P12+N12+L12+J12+H12+F12+D12+X12+Z12 -> 80 | AE12: =AE11+AC12 -> 975 | AF12: =AF11+AD12 -> 709.02 | AG12: =AF12-AE12 -> -265.98 | AH12: spicer | AI12: =+U30+'Punters 2024'!AE12 -> 1584.96 | AJ12: =+V30+'Punters 2024'!AF12 -> 890.66 | AK12: =+AJ12-AI12 -> -694.3 | AL12: =(AJ12-AI12)/AI12 -> -0.43805522
B13: R9 | I13: 25 | J13: 0 | K13: 25 | L13: 0 | M13: 25 | N13: 0 | O13: 25 | P13: 121.88 | Q13: 25 | R13: 0 | AC13: =U13+S13+Q13+O13+M13+K13+I13+G13+E13+C13+W13+Y13 -> 125 | AD13: =V13+T13+R13+P13+N13+L13+J13+H13+F13+D13+X13+Z13 -> 121.88 | AE13: =AE12+AC13 -> 1100 | AF13: =AF12+AD13 -> 830.9 | AG13: =AF13-AE13 -> -269.1 | AH13: ski | AI13: =+I30+'Punters 2024'!AE13 -> 1571.34 | AJ13: =+J30+'Punters 2024'!AF13 -> 809.59 | AK13: =+AJ13-AI13 -> -761.75 | AL13: =(AJ13-AI13)/AI13 -> -0.48477732
B14: R10 | S14: 25 | T14: 0 | U14: 25 | V14: 0 | W14: 25 | X14: 0 | Y14: 25 | Z14: 0 | AC14: =U14+S14+Q14+O14+M14+K14+I14+G14+E14+C14+W14+Y14 -> 100 | AD14: =V14+T14+R14+P14+N14+L14+J14+H14+F14+D14+X14+Z14 -> 0 | AE14: =AE13+AC14 -> 1200 | AF14: =AF13+AD14 -> 830.9 | AG14: =AF14-AE14 -> -369.1 | AH14: cromps | AI14: =+Q30+'Punters 2024'!AE14 -> 1578 | AJ14: =+R30+'Punters 2024'!AF14 -> 772.12 | AK14: =+AJ14-AI14 -> -805.88 | AL14: =(AJ14-AI14)/AI14 -> -0.51069708
B15: R11 | C15: 25 | D15: 0 | E15: 25 | F15: 0 | G15: 25 | H15: 0 | I15: 25 | J15: 183.35 | AC15: =U15+S15+Q15+O15+M15+K15+I15+G15+E15+C15+W15+Y15 -> 100 | AD15: =V15+T15+R15+P15+N15+L15+J15+H15+F15+D15+X15+Z15 -> 183.35 | AE15: =AE14+AC15 -> 1300 | AF15: =AF14+AD15 -> 1014.25 | AG15: =AF15-AE15 -> -285.75 | AH15: scott | AI15: =+O30+'Punters 2024'!AE15 -> 1587.7 | AJ15: =+P30+'Punters 2024'!AF15 -> 2289.85 | AK15: =+AJ15-AI15 -> 702.15 | AL15: =(AJ15-AI15)/AI15 -> 0.4422435
B16: R12 | K16: 25 | L16: 0 | M16: 10 | N16: 0 | O16: 25 | P16: 0 | Q16: 25 | R16: 0 | AC16: =U16+S16+Q16+O16+M16+K16+I16+G16+E16+C16+W16+Y16 -> 85 | AD16: =V16+T16+R16+P16+N16+L16+J16+H16+F16+D16+X16+Z16 -> 0 | AE16: =AE15+AC16 -> 1385 | AF16: =AF15+AD16 -> 1014.25 | AG16: =AF16-AE16 -> -370.75 | AH16: simmo | AI16: =+W30+'Punters 2024'!AE16 -> 820 | AJ16: =+X30+'Punters 2024'!AF16 -> 287.33 | AK16: =+AJ16-AI16 -> -532.67 | AL16: =(AJ16-AI16)/AI16 -> -0.64959756
B17: R13 | M17: 15 | N17: 0 | S17: 25 | T17: 0 | U17: 25 | V17: 0 | W17: 25 | X17: 0 | Y17: 25 | Z17: 0 | AC17: =U17+S17+Q17+O17+M17+K17+I17+G17+E17+C17+W17+Y17 -> 115 | AD17: =V17+T17+R17+P17+N17+L17+J17+H17+F17+D17+X17+Z17 -> 0 | AE17: =AE16+AC17 -> 1500 | AF17: =AF16+AD17 -> 1014.25 | AG17: =AF17-AE17 -> -485.75 | AH17: cam | AI17: =+C30 -> 225 | AJ17: =+D30 -> 125 | AK17: =+AJ17-AI17 -> -100 | AL17: =(AJ17-AI17)/AI17 -> -0.44444444
B18: R14 | C18: 25 | D18: 0 | E18: =5+5+5+10 -> 25 | F18: 0 | G18: 25 | H18: 0 | I18: 25 | J18: 0 | AC18: =U18+S18+Q18+O18+M18+K18+I18+G18+E18+C18+W18+Y18 -> 100 | AD18: =V18+T18+R18+P18+N18+L18+J18+H18+F18+D18+X18+Z18 -> 0 | AE18: =AE17+AC18 -> 1600 | AF18: =AF17+AD18 -> 1014.25 | AG18: =AF18-AE18 -> -585.75 | AH18: pano | AI18: =+G30 -> 231 | AJ18: =+H30 -> 0 | AK18: =+AJ18-AI18 -> -231 | AL18: =(AJ18-AI18)/AI18 -> -1
B19: R15 | K19: 17.5 | L19: 0 | M19: 25 | N19: 0 | O19: 20 | P19: 0 | Q19: 25 | R19: 0 | AC19: =U19+S19+Q19+O19+M19+K19+I19+G19+E19+C19+W19+Y19 -> 87.5 | AD19: =V19+T19+R19+P19+N19+L19+J19+H19+F19+D19+X19+Z19 -> 0 | AE19: =AE18+AC19 -> 1687.5 | AF19: =AF18+AD19 -> 1014.25 | AG19: =AF19-AE19 -> -673.25
